<sdf version='1.6'>
  <world name='default'>
    <model name='ground_plane'>
      <static>1</static>
      <link name='link'>
        <collision name='collision'>
          <geometry>
            <plane>
              <normal>0 0 1</normal>
              <size>100 100</size>
            </plane>
          </geometry>
          <surface>
            <contact>
              <collide_bitmask>65535</collide_bitmask>
              <ode/>
            </contact>
            <friction>
              <ode>
                <mu>100</mu>
                <mu2>50</mu2>
              </ode>
              <torsional>
                <ode/>
              </torsional>
            </friction>
            <bounce/>
          </surface>
          <max_contacts>10</max_contacts>
        </collision>
        <visual name='visual'>
          <cast_shadows>0</cast_shadows>
          <geometry>
            <plane>
              <normal>0 0 1</normal>
              <size>100 100</size>
            </plane>
          </geometry>
          <material>
            <script>
              <uri>file://media/materials/scripts/gazebo.material</uri>
              <name>Gazebo/Grey</name>
            </script>
          </material>
        </visual>
        <self_collide>0</self_collide>
        <kinematic>0</kinematic>
      </link>
    </model>
    <model name='hsrb_square'>
      <link name='link'>
        <pose frame=''>3.2 0 0 0 -0 0</pose>
        <inertial>
          <mass>50</mass>
          <inertia>
            <ixx>1</ixx>
            <ixy>0</ixy>
            <ixz>0</ixz>
            <iyy>1</iyy>
            <iyz>0</iyz>
            <izz>1</izz>
          </inertia>
          <pose frame=''>0 0 0 0 -0 0</pose>
        </inertial>
        <self_collide>0</self_collide>
        <kinematic>0</kinematic>
        <velocity_decay>
          <linear>0</linear>
          <angular>0</angular>
        </velocity_decay>
        <gravity>1</gravity>
        <visual name='bottom_frame'>
          <pose frame=''>0 0 0.05 0 -0 0</pose>
          <geometry>
            <box>
              <size>0.055 6.475 0.1</size>
            </box>
          </geometry>
          <material>
            <script>
              <uri>model://base_materials/color/scripts</uri>
              <name>hsr_color/white</name>
            </script>
            <shader type='pixel'>
              <normal_map>__default__</normal_map>
            </shader>
            <ambient>1 1 1 1</ambient>
            <diffuse>0.5 0.5 0.5 1</diffuse>
            <specular>0 0 0 1</specular>
            <emissive>0 0 0 1</emissive>
          </material>
          <transparency>0</transparency>
          <cast_shadows>1</cast_shadows>
        </visual>
        <visual name='wall'>
          <pose frame=''>0 0 1.095 0 -0 0</pose>
          <geometry>
            <box>
              <size>0.055 6.475 1.99</size>
            </box>
          </geometry>
          <material>
            <script>
              <uri>model://base_materials/wall/scripts</uri>
              <uri>model://base_materials/wall/textures</uri>
              <name>wall/white_noise</name>
            </script>
            <shader type='pixel'>
              <normal_map>__default__</normal_map>
            </shader>
            <ambient>1 1 1 1</ambient>
            <diffuse>0.5 0.5 0.5 1</diffuse>
            <specular>0 0 0 1</specular>
            <emissive>0 0 0 1</emissive>
          </material>
          <transparency>0</transparency>
          <cast_shadows>1</cast_shadows>
        </visual>
        <collision name='collision_bottom_frame'>
          <laser_retro>0</laser_retro>
          <max_contacts>10</max_contacts>
          <pose frame=''>0 0 0.05 0 -0 0</pose>
          <geometry>
            <box>
              <size>0.055 6.475 0.1</size>
            </box>
          </geometry>
          <surface>
            <friction>
              <ode>
                <mu>1</mu>
                <mu2>1</mu2>
                <fdir1>0 0 0</fdir1>
                <slip1>0</slip1>
                <slip2>0</slip2>
              </ode>
              <torsional>
                <coefficient>1</coefficient>
                <patch_radius>0</patch_radius>
                <surface_radius>0</surface_radius>
                <use_patch_radius>1</use_patch_radius>
                <ode>
                  <slip>0</slip>
                </ode>
              </torsional>
            </friction>
            <bounce>
              <restitution_coefficient>0</restitution_coefficient>
              <threshold>1e+06</threshold>
            </bounce>
            <contact>
              <collide_without_contact>0</collide_without_contact>
              <collide_without_contact_bitmask>1</collide_without_contact_bitmask>
              <collide_bitmask>1</collide_bitmask>
              <ode>
                <soft_cfm>0</soft_cfm>
                <soft_erp>0.2</soft_erp>
                <kp>1e+13</kp>
                <kd>1</kd>
                <max_vel>0.01</max_vel>
                <min_depth>0</min_depth>
              </ode>
              <bullet>
                <split_impulse>1</split_impulse>
                <split_impulse_penetration_threshold>-0.01</split_impulse_penetration_threshold>
                <soft_cfm>0</soft_cfm>
                <soft_erp>0.2</soft_erp>
                <kp>1e+13</kp>
                <kd>1</kd>
              </bullet>
            </contact>
          </surface>
        </collision>
        <collision name='collision_wall'>
          <laser_retro>0</laser_retro>
          <max_contacts>10</max_contacts>
          <pose frame=''>0 0 1.095 0 -0 0</pose>
          <geometry>
            <box>
              <size>0.055 6.475 1.99</size>
            </box>
          </geometry>
          <surface>
            <friction>
              <ode>
                <mu>1</mu>
                <mu2>1</mu2>
                <fdir1>0 0 0</fdir1>
                <slip1>0</slip1>
                <slip2>0</slip2>
              </ode>
              <torsional>
                <coefficient>1</coefficient>
                <patch_radius>0</patch_radius>
                <surface_radius>0</surface_radius>
                <use_patch_radius>1</use_patch_radius>
                <ode>
                  <slip>0</slip>
                </ode>
              </torsional>
            </friction>
            <bounce>
              <restitution_coefficient>0</restitution_coefficient>
              <threshold>1e+06</threshold>
            </bounce>
            <contact>
              <collide_without_contact>0</collide_without_contact>
              <collide_without_contact_bitmask>1</collide_without_contact_bitmask>
              <collide_bitmask>1</collide_bitmask>
              <ode>
                <soft_cfm>0</soft_cfm>
                <soft_erp>0.2</soft_erp>
                <kp>1e+13</kp>
                <kd>1</kd>
                <max_vel>0.01</max_vel>
                <min_depth>0</min_depth>
              </ode>
              <bullet>
                <split_impulse>1</split_impulse>
                <split_impulse_penetration_threshold>-0.01</split_impulse_penetration_threshold>
                <soft_cfm>0</soft_cfm>
                <soft_erp>0.2</soft_erp>
                <kp>1e+13</kp>
                <kd>1</kd>
              </bullet>
            </contact>
          </surface>
        </collision>
      </link>
      <link name='link_clone'>
        <pose frame=''>-3.2 0 0 0 -0 0</pose>
        <inertial>
          <mass>50</mass>
          <inertia>
            <ixx>1</ixx>
            <ixy>0</ixy>
            <ixz>0</ixz>
            <iyy>1</iyy>
            <iyz>0</iyz>
            <izz>1</izz>
          </inertia>
          <pose frame=''>0 0 0 0 -0 0</pose>
        </inertial>
        <self_collide>0</self_collide>
        <kinematic>0</kinematic>
        <velocity_decay>
          <linear>0</linear>
          <angular>0</angular>
        </velocity_decay>
        <gravity>1</gravity>
        <visual name='wall'>
          <pose frame=''>0 0 1.095 0 -0 0</pose>
          <geometry>
            <box>
              <size>0.055 6.475 1.99</size>
            </box>
          </geometry>
          <material>
            <script>
              <uri>model://base_materials/wall/scripts</uri>
              <uri>model://base_materials/wall/textures</uri>
              <name>wall/white_noise</name>
            </script>
            <shader type='pixel'>
              <normal_map>__default__</normal_map>
            </shader>
            <ambient>1 1 1 1</ambient>
            <diffuse>0.5 0.5 0.5 1</diffuse>
            <specular>0 0 0 1</specular>
            <emissive>0 0 0 1</emissive>
          </material>
          <transparency>0</transparency>
          <cast_shadows>1</cast_shadows>
        </visual>
        <visual name='bottom_frame'>
          <pose frame=''>0 0 0.05 0 -0 0</pose>
          <geometry>
            <box>
              <size>0.055 6.475 0.1</size>
            </box>
          </geometry>
          <material>
            <script>
              <uri>model://base_materials/color/scripts</uri>
              <name>hsr_color/white</name>
            </script>
            <shader type='pixel'>
              <normal_map>__default__</normal_map>
            </shader>
            <ambient>1 1 1 1</ambient>
            <diffuse>0.5 0.5 0.5 1</diffuse>
            <specular>0 0 0 1</specular>
            <emissive>0 0 0 1</emissive>
          </material>
          <transparency>0</transparency>
          <cast_shadows>1</cast_shadows>
        </visual>
        <collision name='collision_bottom_frame'>
          <laser_retro>0</laser_retro>
          <max_contacts>10</max_contacts>
          <pose frame=''>0 0 0.05 0 -0 0</pose>
          <geometry>
            <box>
              <size>0.055 6.475 0.1</size>
            </box>
          </geometry>
          <surface>
            <friction>
              <ode>
                <mu>1</mu>
                <mu2>1</mu2>
                <fdir1>0 0 0</fdir1>
                <slip1>0</slip1>
                <slip2>0</slip2>
              </ode>
              <torsional>
                <coefficient>1</coefficient>
                <patch_radius>0</patch_radius>
                <surface_radius>0</surface_radius>
                <use_patch_radius>1</use_patch_radius>
                <ode>
                  <slip>0</slip>
                </ode>
              </torsional>
            </friction>
            <bounce>
              <restitution_coefficient>0</restitution_coefficient>
              <threshold>1e+06</threshold>
            </bounce>
            <contact>
              <collide_without_contact>0</collide_without_contact>
              <collide_without_contact_bitmask>1</collide_without_contact_bitmask>
              <collide_bitmask>1</collide_bitmask>
              <ode>
                <soft_cfm>0</soft_cfm>
                <soft_erp>0.2</soft_erp>
                <kp>1e+13</kp>
                <kd>1</kd>
                <max_vel>0.01</max_vel>
                <min_depth>0</min_depth>
              </ode>
              <bullet>
                <split_impulse>1</split_impulse>
                <split_impulse_penetration_threshold>-0.01</split_impulse_penetration_threshold>
                <soft_cfm>0</soft_cfm>
                <soft_erp>0.2</soft_erp>
                <kp>1e+13</kp>
                <kd>1</kd>
              </bullet>
            </contact>
          </surface>
        </collision>
        <collision name='collision_wall'>
          <laser_retro>0</laser_retro>
          <max_contacts>10</max_contacts>
          <pose frame=''>0 0 1.095 0 -0 0</pose>
          <geometry>
            <box>
              <size>0.055 6.475 1.99</size>
            </box>
          </geometry>
          <surface>
            <friction>
              <ode>
                <mu>1</mu>
                <mu2>1</mu2>
                <fdir1>0 0 0</fdir1>
                <slip1>0</slip1>
                <slip2>0</slip2>
              </ode>
              <torsional>
                <coefficient>1</coefficient>
                <patch_radius>0</patch_radius>
                <surface_radius>0</surface_radius>
                <use_patch_radius>1</use_patch_radius>
                <ode>
                  <slip>0</slip>
                </ode>
              </torsional>
            </friction>
            <bounce>
              <restitution_coefficient>0</restitution_coefficient>
              <threshold>1e+06</threshold>
            </bounce>
            <contact>
              <collide_without_contact>0</collide_without_contact>
              <collide_without_contact_bitmask>1</collide_without_contact_bitmask>
              <collide_bitmask>1</collide_bitmask>
              <ode>
                <soft_cfm>0</soft_cfm>
                <soft_erp>0.2</soft_erp>
                <kp>1e+13</kp>
                <kd>1</kd>
                <max_vel>0.01</max_vel>
                <min_depth>0</min_depth>
              </ode>
              <bullet>
                <split_impulse>1</split_impulse>
                <split_impulse_penetration_threshold>-0.01</split_impulse_penetration_threshold>
                <soft_cfm>0</soft_cfm>
                <soft_erp>0.2</soft_erp>
                <kp>1e+13</kp>
                <kd>1</kd>
              </bullet>
            </contact>
          </surface>
        </collision>
      </link>
      <link name='link_clone_clone'>
        <pose frame=''>0 3.2 0 0 -0 1.57</pose>
        <inertial>
          <mass>50</mass>
          <inertia>
            <ixx>1</ixx>
            <ixy>0</ixy>
            <ixz>0</ixz>
            <iyy>1</iyy>
            <iyz>0</iyz>
            <izz>1</izz>
          </inertia>
          <pose frame=''>0 0 0 0 -0 0</pose>
        </inertial>
        <self_collide>0</self_collide>
        <kinematic>0</kinematic>
        <velocity_decay>
          <linear>0</linear>
          <angular>0</angular>
        </velocity_decay>
        <gravity>1</gravity>
        <visual name='wall'>
          <pose frame=''>0 0 1.095 0 -0 0</pose>
          <geometry>
            <box>
              <size>0.055 6.475 1.99</size>
            </box>
          </geometry>
          <material>
            <script>
              <uri>model://base_materials/wall/scripts</uri>
              <uri>model://base_materials/wall/textures</uri>
              <name>wall/white_noise</name>
            </script>
            <shader type='pixel'>
              <normal_map>__default__</normal_map>
            </shader>
            <ambient>1 1 1 1</ambient>
            <diffuse>0.5 0.5 0.5 1</diffuse>
            <specular>0 0 0 1</specular>
            <emissive>0 0 0 1</emissive>
          </material>
          <transparency>0</transparency>
          <cast_shadows>1</cast_shadows>
        </visual>
        <visual name='bottom_frame'>
          <pose frame=''>0 0 0.05 0 -0 0</pose>
          <geometry>
            <box>
              <size>0.055 6.475 0.1</size>
            </box>
          </geometry>
          <material>
            <script>
              <uri>model://base_materials/color/scripts</uri>
              <name>hsr_color/white</name>
            </script>
            <shader type='pixel'>
              <normal_map>__default__</normal_map>
            </shader>
            <ambient>1 1 1 1</ambient>
            <diffuse>0.5 0.5 0.5 1</diffuse>
            <specular>0 0 0 1</specular>
            <emissive>0 0 0 1</emissive>
          </material>
          <transparency>0</transparency>
          <cast_shadows>1</cast_shadows>
        </visual>
        <collision name='collision_wall'>
          <laser_retro>0</laser_retro>
          <max_contacts>10</max_contacts>
          <pose frame=''>0 0 1.095 0 -0 0</pose>
          <geometry>
            <box>
              <size>0.055 6.475 1.99</size>
            </box>
          </geometry>
          <surface>
            <friction>
              <ode>
                <mu>1</mu>
                <mu2>1</mu2>
                <fdir1>0 0 0</fdir1>
                <slip1>0</slip1>
                <slip2>0</slip2>
              </ode>
              <torsional>
                <coefficient>1</coefficient>
                <patch_radius>0</patch_radius>
                <surface_radius>0</surface_radius>
                <use_patch_radius>1</use_patch_radius>
                <ode>
                  <slip>0</slip>
                </ode>
              </torsional>
            </friction>
            <bounce>
              <restitution_coefficient>0</restitution_coefficient>
              <threshold>1e+06</threshold>
            </bounce>
            <contact>
              <collide_without_contact>0</collide_without_contact>
              <collide_without_contact_bitmask>1</collide_without_contact_bitmask>
              <collide_bitmask>1</collide_bitmask>
              <ode>
                <soft_cfm>0</soft_cfm>
                <soft_erp>0.2</soft_erp>
                <kp>1e+13</kp>
                <kd>1</kd>
                <max_vel>0.01</max_vel>
                <min_depth>0</min_depth>
              </ode>
              <bullet>
                <split_impulse>1</split_impulse>
                <split_impulse_penetration_threshold>-0.01</split_impulse_penetration_threshold>
                <soft_cfm>0</soft_cfm>
                <soft_erp>0.2</soft_erp>
                <kp>1e+13</kp>
                <kd>1</kd>
              </bullet>
            </contact>
          </surface>
        </collision>
        <collision name='collision_bottom_frame'>
          <laser_retro>0</laser_retro>
          <max_contacts>10</max_contacts>
          <pose frame=''>0 0 0.05 0 -0 0</pose>
          <geometry>
            <box>
              <size>0.055 6.475 0.1</size>
            </box>
          </geometry>
          <surface>
            <friction>
              <ode>
                <mu>1</mu>
                <mu2>1</mu2>
                <fdir1>0 0 0</fdir1>
                <slip1>0</slip1>
                <slip2>0</slip2>
              </ode>
              <torsional>
                <coefficient>1</coefficient>
                <patch_radius>0</patch_radius>
                <surface_radius>0</surface_radius>
                <use_patch_radius>1</use_patch_radius>
                <ode>
                  <slip>0</slip>
                </ode>
              </torsional>
            </friction>
            <bounce>
              <restitution_coefficient>0</restitution_coefficient>
              <threshold>1e+06</threshold>
            </bounce>
            <contact>
              <collide_without_contact>0</collide_without_contact>
              <collide_without_contact_bitmask>1</collide_without_contact_bitmask>
              <collide_bitmask>1</collide_bitmask>
              <ode>
                <soft_cfm>0</soft_cfm>
                <soft_erp>0.2</soft_erp>
                <kp>1e+13</kp>
                <kd>1</kd>
                <max_vel>0.01</max_vel>
                <min_depth>0</min_depth>
              </ode>
              <bullet>
                <split_impulse>1</split_impulse>
                <split_impulse_penetration_threshold>-0.01</split_impulse_penetration_threshold>
                <soft_cfm>0</soft_cfm>
                <soft_erp>0.2</soft_erp>
                <kp>1e+13</kp>
                <kd>1</kd>
              </bullet>
            </contact>
          </surface>
        </collision>
      </link>
      <link name='link_clone_clone_clone'>
        <pose frame=''>0 -3.2 0 0 -0 1.57</pose>
        <inertial>
          <mass>50</mass>
          <inertia>
            <ixx>1</ixx>
            <ixy>0</ixy>
            <ixz>0</ixz>
            <iyy>1</iyy>
            <iyz>0</iyz>
            <izz>1</izz>
          </inertia>
          <pose frame=''>0 0 0 0 -0 0</pose>
        </inertial>
        <self_collide>0</self_collide>
        <kinematic>0</kinematic>
        <velocity_decay>
          <linear>0</linear>
          <angular>0</angular>
        </velocity_decay>
        <gravity>1</gravity>
        <visual name='wall'>
          <pose frame=''>0 0 1.095 0 -0 0</pose>
          <geometry>
            <box>
              <size>0.055 6.475 1.99</size>
            </box>
          </geometry>
          <material>
            <script>
              <uri>model://base_materials/wall/scripts</uri>
              <uri>model://base_materials/wall/textures</uri>
              <name>wall/white_noise</name>
            </script>
            <shader type='pixel'>
              <normal_map>__default__</normal_map>
            </shader>
            <ambient>1 1 1 1</ambient>
            <diffuse>0.5 0.5 0.5 1</diffuse>
            <specular>0 0 0 1</specular>
            <emissive>0 0 0 1</emissive>
          </material>
          <transparency>0</transparency>
          <cast_shadows>1</cast_shadows>
        </visual>
        <visual name='bottom_frame'>
          <pose frame=''>0 0 0.05 0 -0 0</pose>
          <geometry>
            <box>
              <size>0.055 6.475 0.1</size>
            </box>
          </geometry>
          <material>
            <script>
              <uri>model://base_materials/color/scripts</uri>
              <name>hsr_color/white</name>
            </script>
            <shader type='pixel'>
              <normal_map>__default__</normal_map>
            </shader>
            <ambient>1 1 1 1</ambient>
            <diffuse>0.5 0.5 0.5 1</diffuse>
            <specular>0 0 0 1</specular>
            <emissive>0 0 0 1</emissive>
          </material>
          <transparency>0</transparency>
          <cast_shadows>1</cast_shadows>
        </visual>
        <collision name='collision_wall'>
          <laser_retro>0</laser_retro>
          <max_contacts>10</max_contacts>
          <pose frame=''>0 0 1.095 0 -0 0</pose>
          <geometry>
            <box>
              <size>0.055 6.475 1.99</size>
            </box>
          </geometry>
          <surface>
            <friction>
              <ode>
                <mu>1</mu>
                <mu2>1</mu2>
                <fdir1>0 0 0</fdir1>
                <slip1>0</slip1>
                <slip2>0</slip2>
              </ode>
              <torsional>
                <coefficient>1</coefficient>
                <patch_radius>0</patch_radius>
                <surface_radius>0</surface_radius>
                <use_patch_radius>1</use_patch_radius>
                <ode>
                  <slip>0</slip>
                </ode>
              </torsional>
            </friction>
            <bounce>
              <restitution_coefficient>0</restitution_coefficient>
              <threshold>1e+06</threshold>
            </bounce>
            <contact>
              <collide_without_contact>0</collide_without_contact>
              <collide_without_contact_bitmask>1</collide_without_contact_bitmask>
              <collide_bitmask>1</collide_bitmask>
              <ode>
                <soft_cfm>0</soft_cfm>
                <soft_erp>0.2</soft_erp>
                <kp>1e+13</kp>
                <kd>1</kd>
                <max_vel>0.01</max_vel>
                <min_depth>0</min_depth>
              </ode>
              <bullet>
                <split_impulse>1</split_impulse>
                <split_impulse_penetration_threshold>-0.01</split_impulse_penetration_threshold>
                <soft_cfm>0</soft_cfm>
                <soft_erp>0.2</soft_erp>
                <kp>1e+13</kp>
                <kd>1</kd>
              </bullet>
            </contact>
          </surface>
        </collision>
        <collision name='collision_bottom_frame'>
          <laser_retro>0</laser_retro>
          <max_contacts>10</max_contacts>
          <pose frame=''>0 0 0.05 0 -0 0</pose>
          <geometry>
            <box>
              <size>0.055 6.475 0.1</size>
            </box>
          </geometry>
          <surface>
            <friction>
              <ode>
                <mu>1</mu>
                <mu2>1</mu2>
                <fdir1>0 0 0</fdir1>
                <slip1>0</slip1>
                <slip2>0</slip2>
              </ode>
              <torsional>
                <coefficient>1</coefficient>
                <patch_radius>0</patch_radius>
                <surface_radius>0</surface_radius>
                <use_patch_radius>1</use_patch_radius>
                <ode>
                  <slip>0</slip>
                </ode>
              </torsional>
            </friction>
            <bounce>
              <restitution_coefficient>0</restitution_coefficient>
              <threshold>1e+06</threshold>
            </bounce>
            <contact>
              <collide_without_contact>0</collide_without_contact>
              <collide_without_contact_bitmask>1</collide_without_contact_bitmask>
              <collide_bitmask>1</collide_bitmask>
              <ode>
                <soft_cfm>0</soft_cfm>
                <soft_erp>0.2</soft_erp>
                <kp>1e+13</kp>
                <kd>1</kd>
                <max_vel>0.01</max_vel>
                <min_depth>0</min_depth>
              </ode>
              <bullet>
                <split_impulse>1</split_impulse>
                <split_impulse_penetration_threshold>-0.01</split_impulse_penetration_threshold>
                <soft_cfm>0</soft_cfm>
                <soft_erp>0.2</soft_erp>
                <kp>1e+13</kp>
                <kd>1</kd>
              </bullet>
            </contact>
          </surface>
        </collision>
      </link>
      <static>1</static>
      <allow_auto_disable>1</allow_auto_disable>
    </model>
    <physics name='default_physics' default='0' type='ode'>
      <real_time_update_rate>1000</real_time_update_rate>
      <max_step_size>0.001</max_step_size>
      <real_time_factor>1</real_time_factor>
      <ode>
        <solver>
          <type>quick</type>
          <iters>150</iters>
          <precon_iters>0</precon_iters>
          <sor>1.4</sor>
          <use_dynamic_moi_rescaling>1</use_dynamic_moi_rescaling>
        </solver>
        <constraints>
          <cfm>1e-05</cfm>
          <erp>0.2</erp>
          <contact_max_correcting_vel>2000</contact_max_correcting_vel>
          <contact_surface_layer>0.01</contact_surface_layer>
        </constraints>
      </ode>
    </physics>
    <scene>
      <ambient>0.4 0.4 0.4 1</ambient>
      <background>0.7 0.7 0.7 1</background>
      <shadows>1</shadows>
    </scene>
    <model name='hsrb'>
      <link name='base_footprint'>
        <pose frame=''>0 0 0 0 -0 0</pose>
        <inertial>
          <pose frame=''>-0.025934 -0.00547 0.176333 0 -0 0</pose>
          <mass>50.02</mass>
          <inertia>
            <ixx>0.376384</ixx>
            <ixy>0.000387825</ixy>
            <ixz>0.0308632</ixz>
            <iyy>0.345982</iyy>
            <iyz>0.0177433</iyz>
            <izz>0.153464</izz>
          </inertia>
        </inertial>
        <collision name='base_footprint_fixed_joint_lump__base_link_collision'>
          <pose frame=''>0 0 0 0 -0 0</pose>
          <geometry>
            <mesh>
              <scale>1 1 1</scale>
              <uri>/opt/ros/kinetic/share/hsrb_description/meshes/base_v2/base.stl</uri>
            </mesh>
          </geometry>
          <surface>
            <contact>
              <ode/>
            </contact>
            <friction>
              <ode>
                <mu>0.9</mu>
                <mu2>0.9</mu2>
              </ode>
              <torsional>
                <ode/>
              </torsional>
            </friction>
            <bounce/>
          </surface>
          <max_contacts>10</max_contacts>
        </collision>
        <collision name='base_footprint_fixed_joint_lump__base_range_sensor_link_collision_1'>
          <pose frame=''>0.1675 0 0.1844 0 -0 0</pose>
          <geometry>
            <mesh>
              <scale>1 1 1</scale>
              <uri>/opt/ros/kinetic/share/hsrb_parts_description/meshes/sensors/laser.stl</uri>
            </mesh>
          </geometry>
          <surface>
            <contact>
              <ode/>
            </contact>
            <friction>
              <ode>
                <mu>0.9</mu>
                <mu2>0.9</mu2>
              </ode>
              <torsional>
                <ode/>
              </torsional>
            </friction>
            <bounce/>
          </surface>
          <max_contacts>10</max_contacts>
        </collision>
        <visual name='base_footprint_fixed_joint_lump__base_link_visual'>
          <pose frame=''>0 0 0 0 -0 0</pose>
          <geometry>
            <mesh>
              <scale>1 1 1</scale>
              <uri>/opt/ros/kinetic/share/hsrb_description/meshes/base_v2/base_light.dae</uri>
            </mesh>
          </geometry>
          <material>
            <script>
              <uri>__default__</uri>
              <name>__default__</name>
            </script>
          </material>
        </visual>
        <visual name='base_footprint_fixed_joint_lump__base_link_visual_1'>
          <pose frame=''>0 0 0 0 -0 0</pose>
          <geometry>
            <mesh>
              <scale>1 1 1</scale>
              <uri>/opt/ros/kinetic/share/hsrb_description/meshes/base_v2/body_light.dae</uri>
            </mesh>
          </geometry>
          <material>
            <script>
              <uri>__default__</uri>
              <name>__default__</name>
            </script>
          </material>
        </visual>
        <visual name='base_footprint_fixed_joint_lump__base_link_visual_2'>
          <pose frame=''>0 0 0 0 -0 0</pose>
          <geometry>
            <mesh>
              <scale>1 1 1</scale>
              <uri>/opt/ros/kinetic/share/hsrb_description/meshes/base_v2/torso_base.dae</uri>
            </mesh>
          </geometry>
          <material>
            <script>
              <uri>__default__</uri>
              <name>__default__</name>
            </script>
          </material>
        </visual>
        <visual name='base_footprint_fixed_joint_lump__base_range_sensor_link_visual_3'>
          <pose frame=''>0.1675 0 0.1844 0 -0 0</pose>
          <geometry>
            <mesh>
              <scale>1 1 1</scale>
              <uri>/opt/ros/kinetic/share/hsrb_parts_description/meshes/sensors/laser.dae</uri>
            </mesh>
          </geometry>
          <material>
            <script>
              <uri>__default__</uri>
              <name>__default__</name>
            </script>
          </material>
        </visual>
        <velocity_decay/>
        <velocity_decay/>
        <sensor name='base_imu' type='imu'>
          <update_rate>10</update_rate>
          <plugin name='base_imu_plugin' filename='libgazebo_ros_imu_sensor.so'>
            <updateRateHZ>50.0</updateRateHZ>
            <bodyName>base_link</bodyName>
            <topicName>hsrb/base_imu/data</topicName>
            <frameName>/base_imu_frame</frameName>
            <gaussianNoise>0.0</gaussianNoise>
            <xyzOffset>0.0 0.0 0.0</xyzOffset>
            <rpyOffset>0.0 -0.0 0.0</rpyOffset>
            <robotNamespace>/</robotNamespace>
          </plugin>
          <imu>
            <angular_velocity>
              <x>
                <noise type='gaussian'>
                  <mean>0</mean>
                  <stddev>0.0002</stddev>
                  <bias_mean>7.5e-06</bias_mean>
                  <bias_stddev>8e-07</bias_stddev>
                </noise>
              </x>
              <y>
                <noise type='gaussian'>
                  <mean>0</mean>
                  <stddev>0.0002</stddev>
                  <bias_mean>7.5e-06</bias_mean>
                  <bias_stddev>8e-07</bias_stddev>
                </noise>
              </y>
              <z>
                <noise type='gaussian'>
                  <mean>0</mean>
                  <stddev>0.0002</stddev>
                  <bias_mean>7.5e-06</bias_mean>
                  <bias_stddev>8e-07</bias_stddev>
                </noise>
              </z>
            </angular_velocity>
            <linear_acceleration>
              <x>
                <noise type='gaussian'>
                  <mean>0</mean>
                  <stddev>0.017</stddev>
                  <bias_mean>0.1</bias_mean>
                  <bias_stddev>0.001</bias_stddev>
                </noise>
              </x>
              <y>
                <noise type='gaussian'>
                  <mean>0</mean>
                  <stddev>0.017</stddev>
                  <bias_mean>0.1</bias_mean>
                  <bias_stddev>0.001</bias_stddev>
                </noise>
              </y>
              <z>
                <noise type='gaussian'>
                  <mean>0</mean>
                  <stddev>0.017</stddev>
                  <bias_mean>0.1</bias_mean>
                  <bias_stddev>0.001</bias_stddev>
                </noise>
              </z>
            </linear_acceleration>
          </imu>
          <pose frame=''>0.0005 0.1296 0.181 0 -0 0</pose>
        </sensor>
        <velocity_decay/>
        <gravity>1</gravity>
        <gravity>1</gravity>
        <velocity_decay/>
        <sensor name='base_range_sensor' type='ray'>
          <update_rate>30</update_rate>
          <visualize>1</visualize>
          <ray>
            <scan>
              <horizontal>
                <samples>180</samples>
                <resolution>1</resolution>
                <min_angle>-2.1</min_angle>
                <max_angle>2.1</max_angle>
              </horizontal>
              <vertical>
                <samples>1</samples>
                <min_angle>0</min_angle>
                <max_angle>0</max_angle>
              </vertical>
            </scan>
            <range>
              <min>0.05</min>
              <max>60</max>
              <resolution>0.001</resolution>
            </range>
          </ray>
          <plugin name='hokuyo_laser' filename='libgazebo_ros_laser.so'>
            <topicName>hsrb/base_scan</topicName>
            <frameName>base_range_sensor_link</frameName>
            <robotNamespace>/</robotNamespace>
          </plugin>
          <pose frame=''>0.1675 0 0.1844 0 -0 0</pose>
        </sensor>
        <gravity>1</gravity>
        <velocity_decay/>
        <self_collide>0</self_collide>
        <gravity>1</gravity>
        <kinematic>0</kinematic>
      </link>
      <link name='arm_lift_link'>
        <pose frame=''>0 0 0.34 0 -0 0</pose>
        <inertial>
          <pose frame=''>0.051549 0.042438 -0.064145 0 -0 0</pose>
          <mass>1.27582</mass>
          <inertia>
            <ixx>0.004633</ixx>
            <ixy>0.000475273</ixy>
            <ixz>-0.002403</ixz>
            <iyy>0.008065</iyy>
            <iyz>-0.000100269</iyz>
            <izz>0.007672</izz>
          </inertia>
        </inertial>
        <collision name='arm_lift_link_collision'>
          <pose frame=''>0 0 0 0 -0 0</pose>
          <geometry>
            <mesh>
              <scale>1 1 1</scale>
              <uri>/opt/ros/kinetic/share/hsrb_description/meshes/arm_v0/shoulder.stl</uri>
            </mesh>
          </geometry>
          <surface>
            <contact>
              <ode/>
            </contact>
            <friction>
              <ode>
                <mu>0.9</mu>
                <mu2>0.9</mu2>
              </ode>
              <torsional>
                <ode/>
              </torsional>
            </friction>
            <bounce/>
          </surface>
          <max_contacts>10</max_contacts>
        </collision>
        <visual name='arm_lift_link_visual'>
          <pose frame=''>0 0 0 0 -0 0</pose>
          <geometry>
            <mesh>
              <scale>1 1 1</scale>
              <uri>/opt/ros/kinetic/share/hsrb_description/meshes/arm_v0/shoulder.dae</uri>
            </mesh>
          </geometry>
          <material>
            <script>
              <uri>__default__</uri>
              <name>__default__</name>
            </script>
          </material>
        </visual>
        <gravity>1</gravity>
        <velocity_decay/>
        <self_collide>0</self_collide>
        <gravity>1</gravity>
        <kinematic>0</kinematic>
      </link>
      <joint name='arm_lift_joint' type='prismatic'>
        <child>arm_lift_link</child>
        <parent>base_footprint</parent>
        <axis>
          <xyz>0 0 1</xyz>
          <limit>
            <lower>0</lower>
            <upper>0.69</upper>
            <effort>300</effort>
            <velocity>0.2</velocity>
          </limit>
          <dynamics>
            <damping>1</damping>
            <friction>0</friction>
            <spring_reference>0</spring_reference>
            <spring_stiffness>0</spring_stiffness>
          </dynamics>
          <use_parent_model_frame>1</use_parent_model_frame>
        </axis>
        <physics>
          <ode>
            <limit>
              <cfm>0</cfm>
              <erp>0.2</erp>
            </limit>
          </ode>
        </physics>
      </joint>
      <link name='arm_flex_link'>
        <pose frame=''>0.141 0.078 0.34 0 -0 0</pose>
        <inertial>
          <pose frame=''>0.000632 0.006404 0.118529 0 -0 0</pose>
          <mass>1.33929</mass>
          <inertia>
            <ixx>7.528</ixx>
            <ixy>-2.02842e-05</ixy>
            <ixz>-2.29472e-05</ixz>
            <iyy>0.007102</iyy>
            <iyz>-9.17961e-05</iyz>
            <izz>0.001552</izz>
          </inertia>
        </inertial>
        <collision name='arm_flex_link_collision'>
          <pose frame=''>0 0 0 0 -0 0</pose>
          <geometry>
            <mesh>
              <scale>1 1 1</scale>
              <uri>/opt/ros/kinetic/share/hsrb_description/meshes/arm_v0/arm_flex.stl</uri>
            </mesh>
          </geometry>
          <surface>
            <contact>
              <ode/>
            </contact>
            <friction>
              <ode>
                <mu>0.9</mu>
                <mu2>0.9</mu2>
              </ode>
              <torsional>
                <ode/>
              </torsional>
            </friction>
            <bounce/>
          </surface>
          <max_contacts>10</max_contacts>
        </collision>
        <visual name='arm_flex_link_visual'>
          <pose frame=''>0 0 0 0 -0 0</pose>
          <geometry>
            <mesh>
              <scale>1 1 1</scale>
              <uri>/opt/ros/kinetic/share/hsrb_description/meshes/arm_v0/arm_flex_light.dae</uri>
            </mesh>
          </geometry>
          <material>
            <script>
              <uri>__default__</uri>
              <name>__default__</name>
            </script>
          </material>
        </visual>
        <gravity>1</gravity>
        <velocity_decay/>
        <self_collide>0</self_collide>
        <gravity>1</gravity>
        <kinematic>0</kinematic>
      </link>
      <joint name='arm_flex_joint' type='revolute'>
        <child>arm_flex_link</child>
        <parent>arm_lift_link</parent>
        <axis>
          <xyz>0 -1 0</xyz>
          <limit>
            <lower>-2.62</lower>
            <upper>0</upper>
            <effort>100</effort>
            <velocity>1.2</velocity>
          </limit>
          <dynamics>
            <damping>1</damping>
            <friction>0</friction>
            <spring_reference>0</spring_reference>
            <spring_stiffness>0</spring_stiffness>
          </dynamics>
          <use_parent_model_frame>1</use_parent_model_frame>
        </axis>
        <physics>
          <ode>
            <limit>
              <cfm>0</cfm>
              <erp>0.2</erp>
            </limit>
          </ode>
        </physics>
      </joint>
      <link name='arm_roll_link'>
        <pose frame=''>0.146 0.078 0.685 0 -0 0</pose>
        <inertial>
          <pose frame=''>-0.006927 0.002039 -0.064837 0 -0 0</pose>
          <mass>0.247936</mass>
          <inertia>
            <ixx>0.004267</ixx>
            <ixy>-1.83222e-05</ixy>
            <ixz>1.79845e-05</ixz>
            <iyy>0.000780924</iyy>
            <iyz>-1.39233e-05</iyz>
            <izz>0.00412</izz>
          </inertia>
        </inertial>
        <collision name='arm_roll_link_collision'>
          <pose frame=''>0 0 0 0 -0 0</pose>
          <geometry>
            <mesh>
              <scale>1 1 1</scale>
              <uri>/opt/ros/kinetic/share/hsrb_description/meshes/arm_v0/arm_roll.stl</uri>
            </mesh>
          </geometry>
          <surface>
            <contact>
              <ode/>
            </contact>
            <friction>
              <ode>
                <mu>0.9</mu>
                <mu2>0.9</mu2>
              </ode>
              <torsional>
                <ode/>
              </torsional>
            </friction>
            <bounce/>
          </surface>
          <max_contacts>10</max_contacts>
        </collision>
        <visual name='arm_roll_link_visual'>
          <pose frame=''>0 0 0 0 -0 0</pose>
          <geometry>
            <mesh>
              <scale>1 1 1</scale>
              <uri>/opt/ros/kinetic/share/hsrb_description/meshes/arm_v0/arm_roll_light.dae</uri>
            </mesh>
          </geometry>
          <material>
            <script>
              <uri>__default__</uri>
              <name>__default__</name>
            </script>
          </material>
        </visual>
        <gravity>1</gravity>
        <velocity_decay/>
        <self_collide>0</self_collide>
        <gravity>1</gravity>
        <kinematic>0</kinematic>
      </link>
      <joint name='arm_roll_joint' type='revolute'>
        <child>arm_roll_link</child>
        <parent>arm_flex_link</parent>
        <axis>
          <xyz>0 0 1</xyz>
          <limit>
            <lower>-2.09</lower>
            <upper>3.84</upper>
            <effort>100</effort>
            <velocity>2</velocity>
          </limit>
          <dynamics>
            <damping>0.1</damping>
            <friction>0</friction>
            <spring_reference>0</spring_reference>
            <spring_stiffness>0</spring_stiffness>
          </dynamics>
          <use_parent_model_frame>1</use_parent_model_frame>
        </axis>
        <physics>
          <ode>
            <limit>
              <cfm>0</cfm>
              <erp>0.2</erp>
            </limit>
          </ode>
        </physics>
      </joint>
      <link name='wrist_flex_link'>
        <pose frame=''>0.146 0.078 0.685 0 -0 0</pose>
        <inertial>
          <pose frame=''>0.000131 -0.003929 0.00217 0 -0 0</pose>
          <mass>0.681225</mass>
          <inertia>
            <ixx>7.43536e-05</ixx>
            <ixy>4.94515e-07</ixy>
            <ixz>2.2937e-08</ixz>
            <iyy>3.84329e-05</iyy>
            <iyz>-2.55576e-06</iyz>
            <izz>6.46809e-05</izz>
          </inertia>
        </inertial>
        <collision name='wrist_flex_link_collision'>
          <pose frame=''>0 0 0.03 0 -0 0</pose>
          <geometry>
            <cylinder>
              <length>0.04</length>
              <radius>0.017</radius>
            </cylinder>
          </geometry>
          <surface>
            <contact>
              <ode/>
            </contact>
            <friction>
              <ode>
                <mu>0.9</mu>
                <mu2>0.9</mu2>
              </ode>
              <torsional>
                <ode/>
              </torsional>
            </friction>
            <bounce/>
          </surface>
          <max_contacts>10</max_contacts>
        </collision>
        <visual name='wrist_flex_link_visual'>
          <pose frame=''>0 0 0 0 -0 0</pose>
          <geometry>
            <mesh>
              <scale>1 1 1</scale>
              <uri>/opt/ros/kinetic/share/hsrb_description/meshes/wrist_v0/wrist_flex.dae</uri>
            </mesh>
          </geometry>
          <material>
            <script>
              <uri>__default__</uri>
              <name>__default__</name>
            </script>
          </material>
        </visual>
        <visual name='wrist_flex_link_visual_1'>
          <pose frame=''>0 0 0.04 0 -0 0</pose>
          <geometry>
            <cylinder>
              <length>0.02</length>
              <radius>0.017</radius>
            </cylinder>
          </geometry>
          <material>
            <script>
              <uri>__default__</uri>
              <name>__default__</name>
            </script>
          </material>
        </visual>
        <gravity>1</gravity>
        <velocity_decay/>
        <self_collide>0</self_collide>
        <gravity>1</gravity>
        <kinematic>0</kinematic>
      </link>
      <joint name='wrist_flex_joint' type='revolute'>
        <child>wrist_flex_link</child>
        <parent>arm_roll_link</parent>
        <axis>
          <xyz>0 -1 0</xyz>
          <limit>
            <lower>-1.92</lower>
            <upper>1.22</upper>
            <effort>100</effort>
            <velocity>1.5</velocity>
          </limit>
          <dynamics>
            <damping>1</damping>
            <friction>0</friction>
            <spring_reference>0</spring_reference>
            <spring_stiffness>0</spring_stiffness>
          </dynamics>
          <use_parent_model_frame>1</use_parent_model_frame>
        </axis>
        <physics>
          <ode>
            <limit>
              <cfm>0</cfm>
              <erp>0.2</erp>
            </limit>
          </ode>
        </physics>
      </joint>
      <link name='wrist_ft_sensor_mount_link'>
        <pose frame=''>0.146 0.078 0.685 0 -0 0</pose>
        <inertial>
          <pose frame=''>0 0 0 0 -0 0</pose>
          <mass>0.01</mass>
          <inertia>
            <ixx>0.001</ixx>
            <ixy>0</ixy>
            <ixz>0</ixz>
            <iyy>0.001</iyy>
            <iyz>0</iyz>
            <izz>0.001</izz>
          </inertia>
        </inertial>
        <self_collide>0</self_collide>
        <kinematic>0</kinematic>
      </link>
      <joint name='wrist_roll_joint' type='revolute'>
        <child>wrist_ft_sensor_mount_link</child>
        <parent>wrist_flex_link</parent>
        <axis>
          <xyz>0 0 1</xyz>
          <limit>
            <lower>-1.92</lower>
            <upper>3.67</upper>
            <effort>100</effort>
            <velocity>1.5</velocity>
          </limit>
          <dynamics>
            <damping>1</damping>
            <friction>0</friction>
            <spring_reference>0</spring_reference>
            <spring_stiffness>0</spring_stiffness>
          </dynamics>
          <use_parent_model_frame>1</use_parent_model_frame>
        </axis>
        <physics>
          <ode>
            <limit>
              <cfm>0</cfm>
              <erp>0.2</erp>
            </limit>
          </ode>
        </physics>
      </joint>
      <link name='wrist_ft_sensor_frame'>
        <pose frame=''>0.146 0.078 0.7585 -3.14159 -0 0</pose>
        <inertial>
          <pose frame=''>0.000193 0.001251 -0.018623 0 -0 0</pose>
          <mass>0.941692</mass>
          <inertia>
            <ixx>0.0192819</ixx>
            <ixy>1.63273e-05</ixy>
            <ixz>4.64339e-05</ixz>
            <iyy>0.0192817</iyy>
            <iyz>1.0165e-05</iyz>
            <izz>0.0184914</izz>
          </inertia>
        </inertial>
        <collision name='wrist_ft_sensor_frame_fixed_joint_lump__wrist_roll_link_collision'>
          <pose frame=''>0 0 0.0735 3.14159 -0 0</pose>
          <geometry>
            <mesh>
              <scale>1 1 1</scale>
              <uri>/opt/ros/kinetic/share/hsrb_description/meshes/wrist_v0/wrist_roll.stl</uri>
            </mesh>
          </geometry>
          <surface>
            <contact>
              <ode/>
            </contact>
            <friction>
              <ode>
                <mu>0.9</mu>
                <mu2>0.9</mu2>
              </ode>
              <torsional>
                <ode/>
              </torsional>
            </friction>
            <bounce/>
          </surface>
          <max_contacts>10</max_contacts>
        </collision>
        <collision name='wrist_ft_sensor_frame_fixed_joint_lump__hand_palm_link_collision_1'>
          <pose frame=''>0.012 -0 -0.067 -3.14159 -0 3.14159</pose>
          <geometry>
            <mesh>
              <scale>1 1 1</scale>
              <uri>/opt/ros/kinetic/share/hsrb_description/meshes/hand_v0/palm.stl</uri>
            </mesh>
          </geometry>
          <surface>
            <contact>
              <ode/>
            </contact>
            <friction>
              <ode>
                <mu>0.9</mu>
                <mu2>0.9</mu2>
              </ode>
              <torsional>
                <ode/>
              </torsional>
            </friction>
            <bounce/>
          </surface>
          <max_contacts>10</max_contacts>
        </collision>
        <visual name='wrist_ft_sensor_frame_fixed_joint_lump__wrist_roll_link_visual'>
          <pose frame=''>0 0 0.0735 3.14159 -0 0</pose>
          <geometry>
            <mesh>
              <scale>1 1 1</scale>
              <uri>/opt/ros/kinetic/share/hsrb_description/meshes/wrist_v0/wrist_roll.dae</uri>
            </mesh>
          </geometry>
          <material>
            <script>
              <uri>__default__</uri>
              <name>__default__</name>
            </script>
          </material>
        </visual>
        <visual name='wrist_ft_sensor_frame_fixed_joint_lump__hand_palm_link_visual_1'>
          <pose frame=''>0.012 -0 -0.067 -3.14159 -0 3.14159</pose>
          <geometry>
            <mesh>
              <scale>1 1 1</scale>
              <uri>/opt/ros/kinetic/share/hsrb_description/meshes/hand_v0/palm_light.dae</uri>
            </mesh>
          </geometry>
          <material>
            <script>
              <uri>__default__</uri>
              <name>__default__</name>
            </script>
          </material>
        </visual>
        <velocity_decay/>
        <velocity_decay/>
        <gravity>1</gravity>
        <velocity_decay/>
        <gravity>1</gravity>
        <gravity>1</gravity>
        <velocity_decay/>
        <self_collide>0</self_collide>
        <gravity>0</gravity>
        <gravity>1</gravity>
        <velocity_decay/>
        <sensor name='hand_camera' type='camera'>
          <update_rate>10</update_rate>
          <camera name='hand_camera'>
            <horizontal_fov>2</horizontal_fov>
            <image>
              <width>640</width>
              <height>480</height>
              <format>R8G8B8</format>
            </image>
            <clip>
              <near>0.01</near>
              <far>100</far>
            </clip>
            <noise>
              <type>gaussian</type>
              <mean>0</mean>
              <stddev>0.007</stddev>
            </noise>
          </camera>
          <plugin name='camera_controller' filename='libhsrb_gazebo_ros_camera.so'>
            <robotNamespace>/hsrb</robotNamespace>
            <alwaysOn>0</alwaysOn>
            <updateRate>0.0</updateRate>
            <cameraName>hand_camera</cameraName>
            <imageTopicName>image_raw</imageTopicName>
            <cameraInfoTopicName>camera_info</cameraInfoTopicName>
            <frameName>hand_camera_frame</frameName>
            <hackBaseline>0.07</hackBaseline>
            <distortionK1>0.0</distortionK1>
            <distortionK2>0.0</distortionK2>
            <distortionK3>0.0</distortionK3>
            <distortionT1>0.0</distortionT1>
            <distortionT2>0.0</distortionT2>
          </plugin>
          <pose frame=''>-0.027 -0 -0.0625 1.61304 1.57079 0.042253</pose>
        </sensor>
        <kinematic>0</kinematic>
      </link>
      <joint name='wrist_ft_sensor_frame_joint' type='revolute'>
        <child>wrist_ft_sensor_frame</child>
        <parent>wrist_ft_sensor_mount_link</parent>
        <axis>
          <xyz>1 0 0</xyz>
          <limit>
            <lower>0</lower>
            <upper>0</upper>
            <effort>100</effort>
            <velocity>1.5</velocity>
          </limit>
          <dynamics>
            <spring_reference>0</spring_reference>
            <spring_stiffness>0</spring_stiffness>
          </dynamics>
          <use_parent_model_frame>1</use_parent_model_frame>
        </axis>
        <physics>
          <provide_feedback>1</provide_feedback>
          <ode>
            <provide_feedback>1</provide_feedback>
            <limit>
              <cfm>0</cfm>
              <erp>0.2</erp>
            </limit>
          </ode>
        </physics>
      </joint>
      <link name='hand_l_proximal_link'>
        <pose frame=''>0.17475 0.1025 0.808 0 -0 -3.14159</pose>
        <inertial>
          <pose frame=''>0 0 0 0 -0 0</pose>
          <mass>0.01</mass>
          <inertia>
            <ixx>0.0015</ixx>
            <ixy>0</ixy>
            <ixz>0</ixz>
            <iyy>0.0015</iyy>
            <iyz>0</iyz>
            <izz>0.0015</izz>
          </inertia>
        </inertial>
        <gravity>1</gravity>
        <velocity_decay/>
        <self_collide>0</self_collide>
        <gravity>1</gravity>
        <kinematic>0</kinematic>
      </link>
      <joint name='hand_l_proximal_joint' type='revolute'>
        <child>hand_l_proximal_link</child>
        <parent>wrist_ft_sensor_frame</parent>
        <axis>
          <xyz>-1 0 0</xyz>
          <limit>
            <lower>-0.798</lower>
            <upper>1.24</upper>
            <effort>100</effort>
            <velocity>1</velocity>
          </limit>
          <dynamics>
            <damping>0.0001</damping>
            <friction>0</friction>
            <spring_reference>0</spring_reference>
            <spring_stiffness>0</spring_stiffness>
          </dynamics>
          <use_parent_model_frame>1</use_parent_model_frame>
        </axis>
        <physics>
          <ode>
            <limit>
              <cfm>0</cfm>
              <erp>0.2</erp>
            </limit>
          </ode>
        </physics>
      </joint>
      <link name='hand_l_spring_proximal_link'>
        <pose frame=''>0.17475 0.1025 0.808 0 -0 -3.14159</pose>
        <inertial>
          <pose frame=''>0.021418 0.00248 0.022688 0 -0 0</pose>
          <mass>0.043589</mass>
          <inertia>
            <ixx>2.60339e-05</ixx>
            <ixy>-1.44078e-07</ixy>
            <ixz>-1.98241e-06</ixz>
            <iyy>2.88248e-05</iyy>
            <iyz>-1.26842e-06</iyz>
            <izz>5.13592e-06</izz>
          </inertia>
        </inertial>
        <collision name='hand_l_spring_proximal_link_collision'>
          <pose frame=''>0 0 0 0 -0 0</pose>
          <geometry>
            <mesh>
              <scale>1 1 1</scale>
              <uri>/opt/ros/kinetic/share/hsrb_description/meshes/hand_v0/l_proximal.stl</uri>
            </mesh>
          </geometry>
          <surface>
            <contact>
              <ode/>
            </contact>
            <friction>
              <ode>
                <mu>1</mu>
                <mu2>1</mu2>
              </ode>
              <torsional>
                <ode/>
              </torsional>
            </friction>
            <bounce/>
          </surface>
          <max_contacts>10</max_contacts>
        </collision>
        <visual name='hand_l_spring_proximal_link_visual'>
          <pose frame=''>0 0 0 0 -0 0</pose>
          <geometry>
            <mesh>
              <scale>1 1 1</scale>
              <uri>/opt/ros/kinetic/share/hsrb_description/meshes/hand_v0/l_proximal.dae</uri>
            </mesh>
          </geometry>
          <material>
            <script>
              <uri>__default__</uri>
              <name>__default__</name>
            </script>
          </material>
        </visual>
        <gravity>1</gravity>
        <velocity_decay/>
        <self_collide>0</self_collide>
        <gravity>1</gravity>
        <kinematic>0</kinematic>
      </link>
      <joint name='hand_l_spring_proximal_joint' type='revolute'>
        <child>hand_l_spring_proximal_link</child>
        <parent>hand_l_proximal_link</parent>
        <axis>
          <xyz>-1 0 0</xyz>
          <limit>
            <lower>0</lower>
            <upper>0.698</upper>
            <effort>10</effort>
            <velocity>1</velocity>
          </limit>
          <dynamics>
            <damping>0.0001</damping>
            <friction>0</friction>
            <spring_reference>0</spring_reference>
            <spring_stiffness>0</spring_stiffness>
          </dynamics>
          <use_parent_model_frame>1</use_parent_model_frame>
        </axis>
        <physics>
          <ode>
            <limit>
              <cfm>0</cfm>
              <erp>0.2</erp>
            </limit>
          </ode>
        </physics>
      </joint>
      <link name='hand_l_mimic_distal_link'>
        <pose frame=''>0.17475 0.1025 0.878 0 -0 -3.14159</pose>
        <inertial>
          <pose frame=''>0 0 0 0 -0 0</pose>
          <mass>0.01</mass>
          <inertia>
            <ixx>0.0015</ixx>
            <ixy>0</ixy>
            <ixz>0</ixz>
            <iyy>0.0015</iyy>
            <iyz>0</iyz>
            <izz>0.0015</izz>
          </inertia>
        </inertial>
        <gravity>1</gravity>
        <velocity_decay/>
        <self_collide>0</self_collide>
        <gravity>1</gravity>
        <kinematic>0</kinematic>
      </link>
      <joint name='hand_l_mimic_distal_joint' type='revolute'>
        <child>hand_l_mimic_distal_link</child>
        <parent>hand_l_spring_proximal_link</parent>
        <axis>
          <xyz>-1 0 0</xyz>
          <limit>
            <lower>-0.698</lower>
            <upper>-0</upper>
            <effort>100</effort>
            <velocity>1</velocity>
          </limit>
          <dynamics>
            <damping>0.0001</damping>
            <friction>0</friction>
            <spring_reference>0</spring_reference>
            <spring_stiffness>0</spring_stiffness>
          </dynamics>
          <use_parent_model_frame>1</use_parent_model_frame>
        </axis>
        <physics>
          <ode>
            <limit>
              <cfm>0</cfm>
              <erp>0.2</erp>
            </limit>
          </ode>
        </physics>
      </joint>
      <link name='hand_l_distal_link'>
        <pose frame=''>0.17475 0.1025 0.878 0 -0 -3.14159</pose>
        <inertial>
          <pose frame=''>0.010963 0.004789 0.026131 0 -0 0</pose>
          <mass>0.047731</mass>
          <inertia>
            <ixx>0.00301442</ixx>
            <ixy>-2.43794e-06</ixy>
            <ixz>1.08454e-08</ixz>
            <iyy>0.00300659</iyy>
            <iyz>-1.38829e-06</iyz>
            <izz>0.00300979</izz>
          </inertia>
        </inertial>
        <collision name='hand_l_distal_link_collision'>
          <pose frame=''>0 0 0 0 -0 0</pose>
          <geometry>
            <mesh>
              <scale>1 1 1</scale>
              <uri>/opt/ros/kinetic/share/hsrb_description/meshes/hand_v0/l_distal.stl</uri>
            </mesh>
          </geometry>
          <surface>
            <contact>
              <ode/>
            </contact>
            <friction>
              <ode>
                <mu>1</mu>
                <mu2>1</mu2>
              </ode>
              <torsional>
                <ode/>
              </torsional>
            </friction>
            <bounce/>
          </surface>
          <max_contacts>10</max_contacts>
        </collision>
        <visual name='hand_l_distal_link_visual'>
          <pose frame=''>0 0 0 0 -0 0</pose>
          <geometry>
            <mesh>
              <scale>1 1 1</scale>
              <uri>/opt/ros/kinetic/share/hsrb_description/meshes/hand_v0/l_distal.dae</uri>
            </mesh>
          </geometry>
          <material>
            <script>
              <uri>__default__</uri>
              <name>__default__</name>
            </script>
          </material>
        </visual>
        <visual name='hand_l_distal_link_fixed_joint_lump__hand_l_finger_vacuum_frame_visual_1'>
          <pose frame=''>0.00475 -0.004468 0.026149 0.785398 -0 0</pose>
          <geometry>
            <box>
              <size>0.008 0.008 0.02</size>
            </box>
          </geometry>
          <material>
            <script>
              <uri>__default__</uri>
              <name>__default__</name>
            </script>
          </material>
        </visual>
        <velocity_decay/>
        <gravity>1</gravity>
        <velocity_decay/>
        <gravity>0</gravity>
        <gravity>1</gravity>
        <velocity_decay/>
        <self_collide>0</self_collide>
        <gravity>0</gravity>
        <kinematic>0</kinematic>
      </link>
      <joint name='hand_l_distal_joint' type='revolute'>
        <child>hand_l_distal_link</child>
        <parent>hand_l_mimic_distal_link</parent>
        <axis>
          <xyz>-1 0 0</xyz>
          <limit>
            <lower>-1.24</lower>
            <upper>0.798</upper>
            <effort>100</effort>
            <velocity>1</velocity>
          </limit>
          <dynamics>
            <damping>0.0001</damping>
            <friction>0</friction>
            <spring_reference>0</spring_reference>
            <spring_stiffness>0</spring_stiffness>
          </dynamics>
          <use_parent_model_frame>1</use_parent_model_frame>
        </axis>
        <physics>
          <ode>
            <limit>
              <cfm>0</cfm>
              <erp>0.2</erp>
            </limit>
          </ode>
        </physics>
      </joint>
      <link name='hand_motor_dummy_link'>
        <pose frame=''>0.158 0.078 0.8255 0 -0 -3.14159</pose>
        <inertial>
          <pose frame=''>0 0 0 0 -0 0</pose>
          <mass>0.01</mass>
          <inertia>
            <ixx>0.0015</ixx>
            <ixy>0</ixy>
            <ixz>0</ixz>
            <iyy>0.0015</iyy>
            <iyz>0</iyz>
            <izz>0.0015</izz>
          </inertia>
        </inertial>
        <self_collide>0</self_collide>
        <kinematic>0</kinematic>
      </link>
      <joint name='hand_motor_joint' type='revolute'>
        <child>hand_motor_dummy_link</child>
        <parent>wrist_ft_sensor_frame</parent>
        <axis>
          <xyz>-1 0 0</xyz>
          <limit>
            <lower>-0.798</lower>
            <upper>1.24</upper>
            <effort>100</effort>
            <velocity>1</velocity>
          </limit>
          <dynamics>
            <damping>0.0001</damping>
            <friction>0</friction>
            <spring_reference>0</spring_reference>
            <spring_stiffness>0</spring_stiffness>
          </dynamics>
          <use_parent_model_frame>1</use_parent_model_frame>
        </axis>
        <physics>
          <ode>
            <limit>
              <cfm>0</cfm>
              <erp>0.2</erp>
            </limit>
          </ode>
        </physics>
      </joint>
      <link name='hand_r_proximal_link'>
        <pose frame=''>0.17475 0.0535 0.808 0 -0 -3.14159</pose>
        <inertial>
          <pose frame=''>0 0 0 0 -0 0</pose>
          <mass>0.01</mass>
          <inertia>
            <ixx>0.0015</ixx>
            <ixy>0</ixy>
            <ixz>0</ixz>
            <iyy>0.0015</iyy>
            <iyz>0</iyz>
            <izz>0.0015</izz>
          </inertia>
        </inertial>
        <gravity>1</gravity>
        <velocity_decay/>
        <self_collide>0</self_collide>
        <gravity>1</gravity>
        <kinematic>0</kinematic>
      </link>
      <joint name='hand_r_proximal_joint' type='revolute'>
        <child>hand_r_proximal_link</child>
        <parent>wrist_ft_sensor_frame</parent>
        <axis>
          <xyz>1 0 0</xyz>
          <limit>
            <lower>-0.798</lower>
            <upper>1.24</upper>
            <effort>100</effort>
            <velocity>1</velocity>
          </limit>
          <dynamics>
            <damping>0.0001</damping>
            <friction>0</friction>
            <spring_reference>0</spring_reference>
            <spring_stiffness>0</spring_stiffness>
          </dynamics>
          <use_parent_model_frame>1</use_parent_model_frame>
        </axis>
        <physics>
          <ode>
            <limit>
              <cfm>0</cfm>
              <erp>0.2</erp>
            </limit>
          </ode>
        </physics>
      </joint>
      <link name='hand_r_spring_proximal_link'>
        <pose frame=''>0.17475 0.0535 0.808 0 -0 -3.14159</pose>
        <inertial>
          <pose frame=''>0.013203 0.002096 0.023311 0 -0 0</pose>
          <mass>0.043956</mass>
          <inertia>
            <ixx>2.62366e-05</ixx>
            <ixy>1.631e-08</ixy>
            <ixz>1.28184e-06</ixz>
            <iyy>2.88382e-05</iyy>
            <iyz>-1.62171e-06</iyz>
            <izz>4.95715e-06</izz>
          </inertia>
        </inertial>
        <collision name='hand_r_spring_proximal_link_collision'>
          <pose frame=''>0 0 0 0 -0 0</pose>
          <geometry>
            <mesh>
              <scale>1 1 1</scale>
              <uri>/opt/ros/kinetic/share/hsrb_description/meshes/hand_v0/r_proximal.stl</uri>
            </mesh>
          </geometry>
          <surface>
            <contact>
              <ode/>
            </contact>
            <friction>
              <ode>
                <mu>1</mu>
                <mu2>1</mu2>
              </ode>
              <torsional>
                <ode/>
              </torsional>
            </friction>
            <bounce/>
          </surface>
          <max_contacts>10</max_contacts>
        </collision>
        <visual name='hand_r_spring_proximal_link_visual'>
          <pose frame=''>0 0 0 0 -0 0</pose>
          <geometry>
            <mesh>
              <scale>1 1 1</scale>
              <uri>/opt/ros/kinetic/share/hsrb_description/meshes/hand_v0/r_proximal.dae</uri>
            </mesh>
          </geometry>
          <material>
            <script>
              <uri>__default__</uri>
              <name>__default__</name>
            </script>
          </material>
        </visual>
        <gravity>1</gravity>
        <velocity_decay/>
        <self_collide>0</self_collide>
        <gravity>1</gravity>
        <kinematic>0</kinematic>
      </link>
      <joint name='hand_r_spring_proximal_joint' type='revolute'>
        <child>hand_r_spring_proximal_link</child>
        <parent>hand_r_proximal_link</parent>
        <axis>
          <xyz>1 0 0</xyz>
          <limit>
            <lower>0</lower>
            <upper>0.698</upper>
            <effort>10</effort>
            <velocity>1</velocity>
          </limit>
          <dynamics>
            <damping>0.0001</damping>
            <friction>0</friction>
            <spring_reference>0</spring_reference>
            <spring_stiffness>0</spring_stiffness>
          </dynamics>
          <use_parent_model_frame>1</use_parent_model_frame>
        </axis>
        <physics>
          <ode>
            <limit>
              <cfm>0</cfm>
              <erp>0.2</erp>
            </limit>
          </ode>
        </physics>
      </joint>
      <link name='hand_r_mimic_distal_link'>
        <pose frame=''>0.17475 0.0535 0.878 0 -0 -3.14159</pose>
        <inertial>
          <pose frame=''>0 0 0 0 -0 0</pose>
          <mass>0.01</mass>
          <inertia>
            <ixx>0.0015</ixx>
            <ixy>0</ixy>
            <ixz>0</ixz>
            <iyy>0.0015</iyy>
            <iyz>0</iyz>
            <izz>0.0015</izz>
          </inertia>
        </inertial>
        <gravity>1</gravity>
        <velocity_decay/>
        <self_collide>0</self_collide>
        <gravity>1</gravity>
        <kinematic>0</kinematic>
      </link>
      <joint name='hand_r_mimic_distal_joint' type='revolute'>
        <child>hand_r_mimic_distal_link</child>
        <parent>hand_r_spring_proximal_link</parent>
        <axis>
          <xyz>1 0 0</xyz>
          <limit>
            <lower>-0.698</lower>
            <upper>-0</upper>
            <effort>100</effort>
            <velocity>1</velocity>
          </limit>
          <dynamics>
            <damping>0.0001</damping>
            <friction>0</friction>
            <spring_reference>0</spring_reference>
            <spring_stiffness>0</spring_stiffness>
          </dynamics>
          <use_parent_model_frame>1</use_parent_model_frame>
        </axis>
        <physics>
          <ode>
            <limit>
              <cfm>0</cfm>
              <erp>0.2</erp>
            </limit>
          </ode>
        </physics>
      </joint>
      <link name='hand_r_distal_link'>
        <pose frame=''>0.17475 0.0535 0.878 0 -0 -3.14159</pose>
        <inertial>
          <pose frame=''>0.015062 -0.011661 0.024418 0 -0 0</pose>
          <mass>0.030927</mass>
          <inertia>
            <ixx>0.00150884</ixx>
            <ixy>1.24771e-07</ixy>
            <ixz>-4.51213e-07</ixz>
            <iyy>0.00150916</iyy>
            <iyz>2.75163e-06</iyz>
            <izz>0.00150357</izz>
          </inertia>
        </inertial>
        <collision name='hand_r_distal_link_collision'>
          <pose frame=''>0 0 0 0 -0 0</pose>
          <geometry>
            <mesh>
              <scale>1 1 1</scale>
              <uri>/opt/ros/kinetic/share/hsrb_description/meshes/hand_v0/r_distal.stl</uri>
            </mesh>
          </geometry>
          <surface>
            <contact>
              <ode/>
            </contact>
            <friction>
              <ode>
                <mu>1</mu>
                <mu2>1</mu2>
              </ode>
              <torsional>
                <ode/>
              </torsional>
            </friction>
            <bounce/>
          </surface>
          <max_contacts>10</max_contacts>
        </collision>
        <visual name='hand_r_distal_link_visual'>
          <pose frame=''>0 0 0 0 -0 0</pose>
          <geometry>
            <mesh>
              <scale>1 1 1</scale>
              <uri>/opt/ros/kinetic/share/hsrb_description/meshes/hand_v0/r_distal.dae</uri>
            </mesh>
          </geometry>
          <material>
            <script>
              <uri>__default__</uri>
              <name>__default__</name>
            </script>
          </material>
        </visual>
        <velocity_decay/>
        <gravity>0</gravity>
        <gravity>1</gravity>
        <velocity_decay/>
        <self_collide>0</self_collide>
        <gravity>0</gravity>
        <kinematic>0</kinematic>
      </link>
      <joint name='hand_r_distal_joint' type='revolute'>
        <child>hand_r_distal_link</child>
        <parent>hand_r_mimic_distal_link</parent>
        <axis>
          <xyz>1 0 0</xyz>
          <limit>
            <lower>-1.24</lower>
            <upper>0.798</upper>
            <effort>100</effort>
            <velocity>1</velocity>
          </limit>
          <dynamics>
            <damping>0.0001</damping>
            <friction>0</friction>
            <spring_reference>0</spring_reference>
            <spring_stiffness>0</spring_stiffness>
          </dynamics>
          <use_parent_model_frame>1</use_parent_model_frame>
        </axis>
        <physics>
          <ode>
            <limit>
              <cfm>0</cfm>
              <erp>0.2</erp>
            </limit>
          </ode>
        </physics>
      </joint>
      <link name='base_b_bumper_link'>
        <pose frame=''>0 0.0013 0 0 -0 -3.14159</pose>
        <inertial>
          <pose frame=''>0 0 0 0 -0 0</pose>
          <mass>0.06</mass>
          <inertia>
            <ixx>0.001437</ixx>
            <ixy>0</ixy>
            <ixz>0</ixz>
            <iyy>0.001437</iyy>
            <iyz>0</iyz>
            <izz>0.002875</izz>
          </inertia>
        </inertial>
        <collision name='base_b_bumper_link_collision'>
          <pose frame=''>0 0 0 0 -0 0</pose>
          <geometry>
            <mesh>
              <scale>1 1 1</scale>
              <uri>/opt/ros/kinetic/share/hsrb_description/meshes/base_v2/bumper.stl</uri>
            </mesh>
          </geometry>
          <surface>
            <contact>
              <ode/>
            </contact>
            <friction>
              <ode>
                <mu>0.9</mu>
                <mu2>0.9</mu2>
              </ode>
              <torsional>
                <ode/>
              </torsional>
            </friction>
            <bounce/>
          </surface>
          <max_contacts>10</max_contacts>
        </collision>
        <visual name='base_b_bumper_link_visual'>
          <pose frame=''>0 0 0 0 -0 0</pose>
          <geometry>
            <mesh>
              <scale>1 1 1</scale>
              <uri>/opt/ros/kinetic/share/hsrb_description/meshes/base_v2/bumper.dae</uri>
            </mesh>
          </geometry>
          <material>
            <script>
              <uri>__default__</uri>
              <name>__default__</name>
            </script>
          </material>
        </visual>
        <gravity>1</gravity>
        <velocity_decay/>
        <self_collide>0</self_collide>
        <gravity>1</gravity>
        <sensor name='base_b_bumper_contact' type='contact'>
          <always_on>1</always_on>
          <update_rate>10</update_rate>
          <contact>
            <collision>base_b_bumper_link_collision</collision>
            <topic>__default_topic__</topic>
          </contact>
          <plugin name='hsrb_gazebo_ros_bumper_controller' filename='libhsrb_gazebo_ros_bumper.so'>
            <robotNamespace>/hsrb</robotNamespace>
            <bumperTopicName>base_b_bumper_sensor</bumperTopicName>
            <frameName>base_b_bumper_link</frameName>
          </plugin>
        </sensor>
        <kinematic>0</kinematic>
      </link>
      <joint name='base_b_bumper_joint' type='revolute'>
        <child>base_b_bumper_link</child>
        <parent>base_footprint</parent>
        <axis>
          <xyz>-1 0 0</xyz>
          <limit>
            <lower>0</lower>
            <upper>0</upper>
            <effort>0</effort>
            <velocity>0</velocity>
          </limit>
          <dynamics>
            <spring_reference>0</spring_reference>
            <spring_stiffness>0</spring_stiffness>
          </dynamics>
          <use_parent_model_frame>1</use_parent_model_frame>
        </axis>
      </joint>
      <link name='base_f_bumper_link'>
        <pose frame=''>0 0 0 0 -0 0</pose>
        <inertial>
          <pose frame=''>0 0 0 0 -0 0</pose>
          <mass>0.06</mass>
          <inertia>
            <ixx>0.001437</ixx>
            <ixy>0</ixy>
            <ixz>0</ixz>
            <iyy>0.001437</iyy>
            <iyz>0</iyz>
            <izz>0.002875</izz>
          </inertia>
        </inertial>
        <collision name='base_f_bumper_link_collision'>
          <pose frame=''>0 0 0 0 -0 0</pose>
          <geometry>
            <mesh>
              <scale>1 1 1</scale>
              <uri>/opt/ros/kinetic/share/hsrb_description/meshes/base_v2/bumper.stl</uri>
            </mesh>
          </geometry>
          <surface>
            <contact>
              <ode/>
            </contact>
            <friction>
              <ode>
                <mu>0.9</mu>
                <mu2>0.9</mu2>
              </ode>
              <torsional>
                <ode/>
              </torsional>
            </friction>
            <bounce/>
          </surface>
          <max_contacts>10</max_contacts>
        </collision>
        <visual name='base_f_bumper_link_visual'>
          <pose frame=''>0 0 0 0 -0 0</pose>
          <geometry>
            <mesh>
              <scale>1 1 1</scale>
              <uri>/opt/ros/kinetic/share/hsrb_description/meshes/base_v2/bumper.dae</uri>
            </mesh>
          </geometry>
          <material>
            <script>
              <uri>__default__</uri>
              <name>__default__</name>
            </script>
          </material>
        </visual>
        <gravity>1</gravity>
        <velocity_decay/>
        <self_collide>0</self_collide>
        <gravity>1</gravity>
        <sensor name='base_f_bumper_contact' type='contact'>
          <always_on>1</always_on>
          <update_rate>10</update_rate>
          <contact>
            <collision>base_f_bumper_link_collision</collision>
            <topic>__default_topic__</topic>
          </contact>
          <plugin name='hsrb_gazebo_ros_bumper_controller' filename='libhsrb_gazebo_ros_bumper.so'>
            <robotNamespace>/hsrb</robotNamespace>
            <bumperTopicName>base_f_bumper_sensor</bumperTopicName>
            <frameName>base_f_bumper_link</frameName>
          </plugin>
        </sensor>
        <kinematic>0</kinematic>
      </link>
      <joint name='base_f_bumper_joint' type='revolute'>
        <child>base_f_bumper_link</child>
        <parent>base_footprint</parent>
        <axis>
          <xyz>1 0 0</xyz>
          <limit>
            <lower>0</lower>
            <upper>0</upper>
            <effort>0</effort>
            <velocity>0</velocity>
          </limit>
          <dynamics>
            <spring_reference>0</spring_reference>
            <spring_stiffness>0</spring_stiffness>
          </dynamics>
          <use_parent_model_frame>1</use_parent_model_frame>
        </axis>
      </joint>
      <link name='base_roll_link'>
        <pose frame=''>0 0 0 0 -0 0</pose>
        <inertial>
          <pose frame=''>-0.019482 0.002191 0.071013 0 -0 0</pose>
          <mass>10.2394</mass>
          <inertia>
            <ixx>0.07671</ixx>
            <ixy>-0.01005</ixy>
            <ixz>0.001749</ixz>
            <iyy>0.09057</iyy>
            <iyz>0.001549</iyz>
            <izz>0.145</izz>
          </inertia>
        </inertial>
        <gravity>1</gravity>
        <velocity_decay/>
        <self_collide>0</self_collide>
        <gravity>1</gravity>
        <kinematic>0</kinematic>
      </link>
      <joint name='base_roll_joint' type='revolute'>
        <child>base_roll_link</child>
        <parent>base_footprint</parent>
        <axis>
          <xyz>0 0 1</xyz>
          <limit>
            <lower>-1e+16</lower>
            <upper>1e+16</upper>
          </limit>
          <dynamics>
            <damping>0.7</damping>
            <friction>0</friction>
            <spring_reference>0</spring_reference>
            <spring_stiffness>0</spring_stiffness>
          </dynamics>
          <use_parent_model_frame>1</use_parent_model_frame>
        </axis>
      </joint>
      <link name='base_l_drive_wheel_link'>
        <pose frame=''>-0.11 0.133 0.04 0 -0 0</pose>
        <inertial>
          <pose frame=''>0 0 0 0 -0 0</pose>
          <mass>0.2</mass>
          <inertia>
            <ixx>0.015</ixx>
            <ixy>0</ixy>
            <ixz>0</ixz>
            <iyy>0.015</iyy>
            <iyz>0</iyz>
            <izz>0.015</izz>
          </inertia>
        </inertial>
        <collision name='base_l_drive_wheel_link_collision'>
          <pose frame=''>0 0 0 1.5708 -0 0</pose>
          <geometry>
            <cylinder>
              <length>0.03</length>
              <radius>0.04</radius>
            </cylinder>
          </geometry>
          <surface>
            <contact>
              <ode>
                <kp>1e+06</kp>
                <kd>10</kd>
                <max_vel>1</max_vel>
                <min_depth>0</min_depth>
              </ode>
            </contact>
            <friction>
              <ode>
                <mu>1</mu>
                <mu2>1</mu2>
              </ode>
              <torsional>
                <ode/>
              </torsional>
            </friction>
            <bounce/>
          </surface>
          <max_contacts>10</max_contacts>
        </collision>
        <visual name='base_l_drive_wheel_link_visual'>
          <pose frame=''>0 0 0 1.5708 -0 0</pose>
          <geometry>
            <cylinder>
              <length>0.03</length>
              <radius>0.04</radius>
            </cylinder>
          </geometry>
          <material>
            <script>
              <name>Gazebo/FlatBlack</name>
              <uri>file://media/materials/scripts/gazebo.material</uri>
            </script>
          </material>
        </visual>
        <gravity>1</gravity>
        <velocity_decay/>
        <self_collide>0</self_collide>
        <gravity>1</gravity>
        <kinematic>0</kinematic>
      </link>
      <joint name='base_l_drive_wheel_joint' type='revolute'>
        <child>base_l_drive_wheel_link</child>
        <parent>base_roll_link</parent>
        <axis>
          <xyz>0 1 0</xyz>
          <limit>
            <lower>-1e+16</lower>
            <upper>1e+16</upper>
          </limit>
          <dynamics>
            <damping>1</damping>
            <friction>0</friction>
            <spring_reference>0</spring_reference>
            <spring_stiffness>0</spring_stiffness>
          </dynamics>
          <use_parent_model_frame>1</use_parent_model_frame>
        </axis>
      </joint>
      <link name='base_l_passive_wheel_x_frame'>
        <pose frame=''>0.1495 0.055 0.03 0 -0 0</pose>
        <inertial>
          <pose frame=''>0 0 0 0 -0 0</pose>
          <mass>0.2</mass>
          <inertia>
            <ixx>0.015</ixx>
            <ixy>0</ixy>
            <ixz>0</ixz>
            <iyy>0.015</iyy>
            <iyz>0</iyz>
            <izz>0.015</izz>
          </inertia>
        </inertial>
        <self_collide>0</self_collide>
        <kinematic>0</kinematic>
      </link>
      <joint name='base_l_passive_wheel_x_frame_joint' type='revolute'>
        <child>base_l_passive_wheel_x_frame</child>
        <parent>base_roll_link</parent>
        <axis>
          <xyz>1 0 0</xyz>
          <limit>
            <lower>-1e+16</lower>
            <upper>1e+16</upper>
          </limit>
          <dynamics>
            <damping>1</damping>
            <friction>0</friction>
            <spring_reference>0</spring_reference>
            <spring_stiffness>0</spring_stiffness>
          </dynamics>
          <use_parent_model_frame>1</use_parent_model_frame>
        </axis>
      </joint>
      <link name='base_l_passive_wheel_y_frame'>
        <pose frame=''>0.1495 0.055 0.03 0 -0 0</pose>
        <inertial>
          <pose frame=''>0 0 0 0 -0 0</pose>
          <mass>0.2</mass>
          <inertia>
            <ixx>0.015</ixx>
            <ixy>0</ixy>
            <ixz>0</ixz>
            <iyy>0.015</iyy>
            <iyz>0</iyz>
            <izz>0.015</izz>
          </inertia>
        </inertial>
        <self_collide>0</self_collide>
        <kinematic>0</kinematic>
      </link>
      <joint name='base_l_passive_wheel_y_frame_joint' type='revolute'>
        <child>base_l_passive_wheel_y_frame</child>
        <parent>base_l_passive_wheel_x_frame</parent>
        <axis>
          <xyz>0 1 0</xyz>
          <limit>
            <lower>-1e+16</lower>
            <upper>1e+16</upper>
          </limit>
          <dynamics>
            <spring_reference>0</spring_reference>
            <spring_stiffness>0</spring_stiffness>
          </dynamics>
          <use_parent_model_frame>1</use_parent_model_frame>
        </axis>
      </joint>
      <link name='base_l_passive_wheel_z_link'>
        <pose frame=''>0.1495 0.055 0.03 0 -0 0</pose>
        <inertial>
          <pose frame=''>0 0 0 0 -0 0</pose>
          <mass>0.2</mass>
          <inertia>
            <ixx>0.015</ixx>
            <ixy>0</ixy>
            <ixz>0</ixz>
            <iyy>0.015</iyy>
            <iyz>0</iyz>
            <izz>0.015</izz>
          </inertia>
        </inertial>
        <collision name='base_l_passive_wheel_z_link_collision'>
          <pose frame=''>0 0 0 0 -0 0</pose>
          <geometry>
            <sphere>
              <radius>0.03</radius>
            </sphere>
          </geometry>
          <surface>
            <contact>
              <ode>
                <max_vel>1</max_vel>
              </ode>
            </contact>
            <friction>
              <ode>
                <mu>0.1</mu>
                <mu2>0.1</mu2>
              </ode>
              <torsional>
                <ode/>
              </torsional>
            </friction>
            <bounce/>
          </surface>
          <max_contacts>10</max_contacts>
        </collision>
        <visual name='base_l_passive_wheel_z_link_visual'>
          <pose frame=''>0 0 0 0 -0 0</pose>
          <geometry>
            <sphere>
              <radius>0.03</radius>
            </sphere>
          </geometry>
          <material>
            <script>
              <name>Gazebo/FlatBlack</name>
              <uri>file://media/materials/scripts/gazebo.material</uri>
            </script>
          </material>
        </visual>
        <gravity>1</gravity>
        <velocity_decay/>
        <self_collide>0</self_collide>
        <gravity>1</gravity>
        <kinematic>0</kinematic>
      </link>
      <joint name='base_l_passive_wheel_z_joint' type='revolute'>
        <child>base_l_passive_wheel_z_link</child>
        <parent>base_l_passive_wheel_y_frame</parent>
        <axis>
          <xyz>0 0 1</xyz>
          <limit>
            <lower>-1e+16</lower>
            <upper>1e+16</upper>
          </limit>
          <dynamics>
            <spring_reference>0</spring_reference>
            <spring_stiffness>0</spring_stiffness>
          </dynamics>
          <use_parent_model_frame>1</use_parent_model_frame>
        </axis>
      </joint>
      <link name='base_r_drive_wheel_link'>
        <pose frame=''>-0.11 -0.133 0.04 0 -0 0</pose>
        <inertial>
          <pose frame=''>0 0 0 0 -0 0</pose>
          <mass>0.2</mass>
          <inertia>
            <ixx>0.015</ixx>
            <ixy>0</ixy>
            <ixz>0</ixz>
            <iyy>0.015</iyy>
            <iyz>0</iyz>
            <izz>0.015</izz>
          </inertia>
        </inertial>
        <collision name='base_r_drive_wheel_link_collision'>
          <pose frame=''>0 0 0 1.5708 -0 0</pose>
          <geometry>
            <cylinder>
              <length>0.03</length>
              <radius>0.04</radius>
            </cylinder>
          </geometry>
          <surface>
            <contact>
              <ode>
                <kp>1e+06</kp>
                <kd>10</kd>
                <max_vel>1</max_vel>
                <min_depth>0</min_depth>
              </ode>
            </contact>
            <friction>
              <ode>
                <mu>1</mu>
                <mu2>1</mu2>
              </ode>
              <torsional>
                <ode/>
              </torsional>
            </friction>
            <bounce/>
          </surface>
          <max_contacts>10</max_contacts>
        </collision>
        <visual name='base_r_drive_wheel_link_visual'>
          <pose frame=''>0 0 0 1.5708 -0 0</pose>
          <geometry>
            <cylinder>
              <length>0.03</length>
              <radius>0.04</radius>
            </cylinder>
          </geometry>
          <material>
            <script>
              <name>Gazebo/FlatBlack</name>
              <uri>file://media/materials/scripts/gazebo.material</uri>
            </script>
          </material>
        </visual>
        <gravity>1</gravity>
        <velocity_decay/>
        <self_collide>0</self_collide>
        <gravity>1</gravity>
        <kinematic>0</kinematic>
      </link>
      <joint name='base_r_drive_wheel_joint' type='revolute'>
        <child>base_r_drive_wheel_link</child>
        <parent>base_roll_link</parent>
        <axis>
          <xyz>0 1 0</xyz>
          <limit>
            <lower>-1e+16</lower>
            <upper>1e+16</upper>
          </limit>
          <dynamics>
            <damping>1</damping>
            <friction>0</friction>
            <spring_reference>0</spring_reference>
            <spring_stiffness>0</spring_stiffness>
          </dynamics>
          <use_parent_model_frame>1</use_parent_model_frame>
        </axis>
      </joint>
      <link name='base_r_passive_wheel_x_frame'>
        <pose frame=''>0.1495 -0.055 0.03 0 -0 0</pose>
        <inertial>
          <pose frame=''>0 0 0 0 -0 0</pose>
          <mass>0.2</mass>
          <inertia>
            <ixx>0.015</ixx>
            <ixy>0</ixy>
            <ixz>0</ixz>
            <iyy>0.015</iyy>
            <iyz>0</iyz>
            <izz>0.015</izz>
          </inertia>
        </inertial>
        <self_collide>0</self_collide>
        <kinematic>0</kinematic>
      </link>
      <joint name='base_r_passive_wheel_x_frame_joint' type='revolute'>
        <child>base_r_passive_wheel_x_frame</child>
        <parent>base_roll_link</parent>
        <axis>
          <xyz>1 0 0</xyz>
          <limit>
            <lower>-1e+16</lower>
            <upper>1e+16</upper>
          </limit>
          <dynamics>
            <damping>1</damping>
            <friction>0</friction>
            <spring_reference>0</spring_reference>
            <spring_stiffness>0</spring_stiffness>
          </dynamics>
          <use_parent_model_frame>1</use_parent_model_frame>
        </axis>
      </joint>
      <link name='base_r_passive_wheel_y_frame'>
        <pose frame=''>0.1495 -0.055 0.03 0 -0 0</pose>
        <inertial>
          <pose frame=''>0 0 0 0 -0 0</pose>
          <mass>0.2</mass>
          <inertia>
            <ixx>0.015</ixx>
            <ixy>0</ixy>
            <ixz>0</ixz>
            <iyy>0.015</iyy>
            <iyz>0</iyz>
            <izz>0.015</izz>
          </inertia>
        </inertial>
        <self_collide>0</self_collide>
        <kinematic>0</kinematic>
      </link>
      <joint name='base_r_passive_wheel_y_frame_joint' type='revolute'>
        <child>base_r_passive_wheel_y_frame</child>
        <parent>base_r_passive_wheel_x_frame</parent>
        <axis>
          <xyz>0 1 0</xyz>
          <limit>
            <lower>-1e+16</lower>
            <upper>1e+16</upper>
          </limit>
          <dynamics>
            <spring_reference>0</spring_reference>
            <spring_stiffness>0</spring_stiffness>
          </dynamics>
          <use_parent_model_frame>1</use_parent_model_frame>
        </axis>
      </joint>
      <link name='base_r_passive_wheel_z_link'>
        <pose frame=''>0.1495 -0.055 0.03 0 -0 0</pose>
        <inertial>
          <pose frame=''>0 0 0 0 -0 0</pose>
          <mass>0.2</mass>
          <inertia>
            <ixx>0.015</ixx>
            <ixy>0</ixy>
            <ixz>0</ixz>
            <iyy>0.015</iyy>
            <iyz>0</iyz>
            <izz>0.015</izz>
          </inertia>
        </inertial>
        <collision name='base_r_passive_wheel_z_link_collision'>
          <pose frame=''>0 0 0 0 -0 0</pose>
          <geometry>
            <sphere>
              <radius>0.03</radius>
            </sphere>
          </geometry>
          <surface>
            <contact>
              <ode>
                <max_vel>1</max_vel>
              </ode>
            </contact>
            <friction>
              <ode>
                <mu>0.1</mu>
                <mu2>0.1</mu2>
              </ode>
              <torsional>
                <ode/>
              </torsional>
            </friction>
            <bounce/>
          </surface>
          <max_contacts>10</max_contacts>
        </collision>
        <visual name='base_r_passive_wheel_z_link_visual'>
          <pose frame=''>0 0 0 0 -0 0</pose>
          <geometry>
            <sphere>
              <radius>0.03</radius>
            </sphere>
          </geometry>
          <material>
            <script>
              <name>Gazebo/FlatBlack</name>
              <uri>file://media/materials/scripts/gazebo.material</uri>
            </script>
          </material>
        </visual>
        <gravity>1</gravity>
        <velocity_decay/>
        <self_collide>0</self_collide>
        <gravity>1</gravity>
        <kinematic>0</kinematic>
      </link>
      <joint name='base_r_passive_wheel_z_joint' type='revolute'>
        <child>base_r_passive_wheel_z_link</child>
        <parent>base_r_passive_wheel_y_frame</parent>
        <axis>
          <xyz>0 0 1</xyz>
          <limit>
            <lower>-1e+16</lower>
            <upper>1e+16</upper>
          </limit>
          <dynamics>
            <spring_reference>0</spring_reference>
            <spring_stiffness>0</spring_stiffness>
          </dynamics>
          <use_parent_model_frame>1</use_parent_model_frame>
        </axis>
      </joint>
      <link name='torso_lift_link'>
        <pose frame=''>0 0 0.752 0 -0 0</pose>
        <inertial>
          <pose frame=''>-0.051142 0.003454 -0.2905 0 -0 0</pose>
          <mass>3.42078</mass>
          <inertia>
            <ixx>0.1045</ixx>
            <ixy>-0.000460885</ixy>
            <ixz>0.00010113</ixz>
            <iyy>0.105</iyy>
            <iyz>0.002941</iyz>
            <izz>0.01284</izz>
          </inertia>
        </inertial>
        <collision name='torso_lift_link_collision'>
          <pose frame=''>0 0 0 0 -0 0</pose>
          <geometry>
            <mesh>
              <scale>1 1 1</scale>
              <uri>/opt/ros/kinetic/share/hsrb_description/meshes/torso_v0/torso.stl</uri>
            </mesh>
          </geometry>
          <surface>
            <contact>
              <ode/>
            </contact>
            <friction>
              <ode>
                <mu>0.9</mu>
                <mu2>0.9</mu2>
              </ode>
              <torsional>
                <ode/>
              </torsional>
            </friction>
            <bounce/>
          </surface>
          <max_contacts>10</max_contacts>
        </collision>
        <visual name='torso_lift_link_visual'>
          <pose frame=''>0 0 0 0 -0 0</pose>
          <geometry>
            <mesh>
              <scale>1 1 1</scale>
              <uri>/opt/ros/kinetic/share/hsrb_description/meshes/torso_v0/torso_light.dae</uri>
            </mesh>
          </geometry>
          <material>
            <script>
              <uri>__default__</uri>
              <name>__default__</name>
            </script>
          </material>
        </visual>
        <gravity>1</gravity>
        <velocity_decay/>
        <self_collide>0</self_collide>
        <gravity>1</gravity>
        <kinematic>0</kinematic>
      </link>
      <joint name='torso_lift_joint' type='prismatic'>
        <child>torso_lift_link</child>
        <parent>base_footprint</parent>
        <axis>
          <xyz>0 0 1</xyz>
          <limit>
            <lower>0</lower>
            <upper>0.345</upper>
            <effort>300</effort>
            <velocity>0.1</velocity>
          </limit>
          <dynamics>
            <damping>500</damping>
            <friction>0</friction>
            <spring_reference>0</spring_reference>
            <spring_stiffness>0</spring_stiffness>
          </dynamics>
          <use_parent_model_frame>1</use_parent_model_frame>
        </axis>
        <physics>
          <ode>
            <limit>
              <cfm>0</cfm>
              <erp>0.2</erp>
            </limit>
          </ode>
        </physics>
      </joint>
      <link name='head_pan_link'>
        <pose frame=''>0 0 0.752 0 -0 0</pose>
        <inertial>
          <pose frame=''>0.001724 -0.001969 -0.028886 0 -0 0</pose>
          <mass>0.571903</mass>
          <inertia>
            <ixx>0.000971142</ixx>
            <ixy>6.17949e-05</ixy>
            <ixz>-0.000113923</ixz>
            <iyy>0.000653355</iyy>
            <iyz>6.90363e-05</iyz>
            <izz>0.000765203</izz>
          </inertia>
        </inertial>
        <collision name='head_pan_link_collision'>
          <pose frame=''>0 0 0 0 -0 0</pose>
          <geometry>
            <mesh>
              <scale>1 1 1</scale>
              <uri>/opt/ros/kinetic/share/hsrb_description/meshes/head_v1/head_pan.stl</uri>
            </mesh>
          </geometry>
          <surface>
            <contact>
              <ode/>
            </contact>
            <friction>
              <ode>
                <mu>0.9</mu>
                <mu2>0.9</mu2>
              </ode>
              <torsional>
                <ode/>
              </torsional>
            </friction>
            <bounce/>
          </surface>
          <max_contacts>10</max_contacts>
        </collision>
        <visual name='head_pan_link_visual'>
          <pose frame=''>0 0 0 0 -0 0</pose>
          <geometry>
            <mesh>
              <scale>1 1 1</scale>
              <uri>/opt/ros/kinetic/share/hsrb_description/meshes/head_v1/head_pan.dae</uri>
            </mesh>
          </geometry>
          <material>
            <script>
              <uri>__default__</uri>
              <name>__default__</name>
            </script>
          </material>
        </visual>
        <gravity>1</gravity>
        <velocity_decay/>
        <self_collide>0</self_collide>
        <gravity>1</gravity>
        <kinematic>0</kinematic>
      </link>
      <joint name='head_pan_joint' type='revolute'>
        <child>head_pan_link</child>
        <parent>torso_lift_link</parent>
        <axis>
          <xyz>0 0 1</xyz>
          <limit>
            <lower>-3.84</lower>
            <upper>1.75</upper>
            <effort>100</effort>
            <velocity>1</velocity>
          </limit>
          <dynamics>
            <damping>1</damping>
            <friction>0</friction>
            <spring_reference>0</spring_reference>
            <spring_stiffness>0</spring_stiffness>
          </dynamics>
          <use_parent_model_frame>1</use_parent_model_frame>
        </axis>
        <physics>
          <ode>
            <limit>
              <cfm>0</cfm>
              <erp>0.2</erp>
            </limit>
          </ode>
        </physics>
      </joint>
      <link name='head_tilt_link'>
        <pose frame=''>0.02 0 0.752 0 -0 0</pose>
        <inertial>
          <pose frame=''>-0.05355 -0.002148 0.117073 0 -0 0</pose>
          <mass>2.2038</mass>
          <inertia>
            <ixx>0.0280002</ixx>
            <ixy>-0.00013599</ixy>
            <ixz>0.00533594</ixz>
            <iyy>0.023706</iyy>
            <iyz>4.7745e-05</iyz>
            <izz>0.0202221</izz>
          </inertia>
        </inertial>
        <collision name='head_tilt_link_collision'>
          <pose frame=''>0 0 0 0 -0 0</pose>
          <geometry>
            <mesh>
              <scale>1 1 1</scale>
              <uri>/opt/ros/kinetic/share/hsrb_description/meshes/head_v1/head.stl</uri>
            </mesh>
          </geometry>
          <surface>
            <contact>
              <ode/>
            </contact>
            <friction>
              <ode>
                <mu>0.9</mu>
                <mu2>0.9</mu2>
              </ode>
              <torsional>
                <ode/>
              </torsional>
            </friction>
            <bounce/>
          </surface>
          <max_contacts>10</max_contacts>
        </collision>
        <collision name='head_tilt_link_collision_1'>
          <pose frame=''>0 0 0 0 -0 0</pose>
          <geometry>
            <mesh>
              <scale>1 1 1</scale>
              <uri>/opt/ros/kinetic/share/hsrb_description/meshes/head_v1/tablet.stl</uri>
            </mesh>
          </geometry>
          <surface>
            <contact>
              <ode/>
            </contact>
            <friction>
              <ode>
                <mu>0.9</mu>
                <mu2>0.9</mu2>
              </ode>
              <torsional>
                <ode/>
              </torsional>
            </friction>
            <bounce/>
          </surface>
          <max_contacts>10</max_contacts>
        </collision>
        <collision name='head_tilt_link_fixed_joint_lump__head_rgbd_sensor_link_collision_2'>
          <pose frame=''>-0.079796 0.022 0.215172 -1.5708 -0 -1.5708</pose>
          <geometry>
            <mesh>
              <scale>1 1 1</scale>
              <uri>/opt/ros/kinetic/share/hsrb_parts_description/meshes/sensors/xtion.stl</uri>
            </mesh>
          </geometry>
          <surface>
            <contact>
              <ode/>
            </contact>
            <friction>
              <ode>
                <mu>0.9</mu>
                <mu2>0.9</mu2>
              </ode>
              <torsional>
                <ode/>
              </torsional>
            </friction>
            <bounce/>
          </surface>
          <max_contacts>10</max_contacts>
        </collision>
        <visual name='head_tilt_link_visual'>
          <pose frame=''>0 0 0 0 -0 0</pose>
          <geometry>
            <mesh>
              <scale>1 1 1</scale>
              <uri>/opt/ros/kinetic/share/hsrb_description/meshes/head_v1/head_upper.dae</uri>
            </mesh>
          </geometry>
          <material>
            <script>
              <uri>__default__</uri>
              <name>__default__</name>
            </script>
          </material>
        </visual>
        <visual name='head_tilt_link_visual_1'>
          <pose frame=''>0 0 0 0 -0 0</pose>
          <geometry>
            <mesh>
              <scale>1 1 1</scale>
              <uri>/opt/ros/kinetic/share/hsrb_description/meshes/head_v1/head_tilt.dae</uri>
            </mesh>
          </geometry>
          <material>
            <script>
              <uri>__default__</uri>
              <name>__default__</name>
            </script>
          </material>
        </visual>
        <visual name='head_tilt_link_visual_2'>
          <pose frame=''>0 0 0 0 -0 0</pose>
          <geometry>
            <mesh>
              <scale>1 1 1</scale>
              <uri>/opt/ros/kinetic/share/hsrb_description/meshes/head_v1/tablet_base.dae</uri>
            </mesh>
          </geometry>
          <material>
            <script>
              <uri>__default__</uri>
              <name>__default__</name>
            </script>
          </material>
        </visual>
        <visual name='head_tilt_link_fixed_joint_lump__head_l_stereo_camera_link_visual_3'>
          <pose frame=''>0.02 0.07 0.061 -1.5708 -0 -1.5708</pose>
          <geometry>
            <mesh>
              <scale>1 1 1</scale>
              <uri>/opt/ros/kinetic/share/hsrb_parts_description/meshes/sensors/head_camera.dae</uri>
            </mesh>
          </geometry>
          <material>
            <script>
              <uri>__default__</uri>
              <name>__default__</name>
            </script>
          </material>
        </visual>
        <visual name='head_tilt_link_fixed_joint_lump__head_r_stereo_camera_link_visual_4'>
          <pose frame=''>0.02 -0.07 0.061 -1.5708 -0 -1.5708</pose>
          <geometry>
            <mesh>
              <scale>1 1 1</scale>
              <uri>/opt/ros/kinetic/share/hsrb_parts_description/meshes/sensors/head_camera.dae</uri>
            </mesh>
          </geometry>
          <material>
            <script>
              <uri>__default__</uri>
              <name>__default__</name>
            </script>
          </material>
        </visual>
        <visual name='head_tilt_link_fixed_joint_lump__head_rgbd_sensor_link_visual_5'>
          <pose frame=''>-0.079796 0.022 0.215172 -1.5708 -0 -1.5708</pose>
          <geometry>
            <mesh>
              <scale>1 1 1</scale>
              <uri>/opt/ros/kinetic/share/hsrb_parts_description/meshes/sensors/xtion.dae</uri>
            </mesh>
          </geometry>
          <material>
            <script>
              <uri>__default__</uri>
              <name>__default__</name>
            </script>
          </material>
        </visual>
        <velocity_decay/>
        <velocity_decay/>
        <velocity_decay/>
        <sensor name='head_center_camera' type='camera'>
          <update_rate>10</update_rate>
          <camera name='head_center_camera'>
            <horizontal_fov>2</horizontal_fov>
            <image>
              <width>640</width>
              <height>480</height>
              <format>R8G8B8</format>
            </image>
            <clip>
              <near>0.01</near>
              <far>100</far>
            </clip>
            <noise>
              <type>gaussian</type>
              <mean>0</mean>
              <stddev>0.007</stddev>
            </noise>
          </camera>
          <plugin name='camera_controller' filename='libhsrb_gazebo_ros_camera.so'>
            <robotNamespace>/hsrb</robotNamespace>
            <alwaysOn>0</alwaysOn>
            <updateRate>0.0</updateRate>
            <cameraName>head_center_camera</cameraName>
            <imageTopicName>image_raw</imageTopicName>
            <cameraInfoTopicName>camera_info</cameraInfoTopicName>
            <frameName>head_center_camera_frame</frameName>
            <hackBaseline>0.07</hackBaseline>
            <distortionK1>0.0</distortionK1>
            <distortionK2>0.0</distortionK2>
            <distortionK3>0.0</distortionK3>
            <distortionT1>0.0</distortionT1>
            <distortionT2>0.0</distortionT2>
          </plugin>
          <pose frame=''>0.0195 0 0.061 0 -0 0</pose>
        </sensor>
        <velocity_decay/>
        <velocity_decay/>
        <sensor name='head_l_stereo_camera' type='camera'>
          <update_rate>4</update_rate>
          <camera name='head_l_stereo_camera'>
            <horizontal_fov>1.16763</horizontal_fov>
            <image>
              <width>1280</width>
              <height>960</height>
              <format>R8G8B8</format>
            </image>
            <clip>
              <near>0.05</near>
              <far>100</far>
            </clip>
            <noise>
              <type>gaussian</type>
              <mean>0</mean>
              <stddev>0.007</stddev>
            </noise>
          </camera>
          <plugin name='camera_controller' filename='libhsrb_gazebo_ros_camera.so'>
            <alwaysOn>0</alwaysOn>
            <updateRate>0.0</updateRate>
            <cameraName>head_l_stereo_camera</cameraName>
            <imageTopicName>image_rect_color</imageTopicName>
            <cameraInfoTopicName>camera_info</cameraInfoTopicName>
            <frameName>head_l_stereo_camera_frame</frameName>
            <robotNamespace>/hsrb</robotNamespace>
            <hackBaseline>0.0</hackBaseline>
            <distortionK1>0.0</distortionK1>
            <distortionK2>0.0</distortionK2>
            <distortionK3>0.0</distortionK3>
            <distortionT1>0.0</distortionT1>
            <distortionT2>0.0</distortionT2>
          </plugin>
          <pose frame=''>0.02 0.07 0.061 0 -0 0</pose>
        </sensor>
        <gravity>1</gravity>
        <velocity_decay/>
        <gravity>1</gravity>
        <gravity>1</gravity>
        <velocity_decay/>
        <sensor name='head_r_stereo_camera' type='camera'>
          <update_rate>4</update_rate>
          <camera name='head_r_stereo_camera'>
            <horizontal_fov>1.16763</horizontal_fov>
            <image>
              <width>1280</width>
              <height>960</height>
              <format>R8G8B8</format>
            </image>
            <clip>
              <near>0.05</near>
              <far>100</far>
            </clip>
            <noise>
              <type>gaussian</type>
              <mean>0</mean>
              <stddev>0.007</stddev>
            </noise>
          </camera>
          <plugin name='camera_controller' filename='libhsrb_gazebo_ros_camera.so'>
            <alwaysOn>0</alwaysOn>
            <updateRate>0.0</updateRate>
            <cameraName>head_r_stereo_camera</cameraName>
            <imageTopicName>image_rect_color</imageTopicName>
            <cameraInfoTopicName>camera_info</cameraInfoTopicName>
            <frameName>head_r_stereo_camera_frame</frameName>
            <robotNamespace>/hsrb</robotNamespace>
            <hackBaseline>0.14</hackBaseline>
            <distortionK1>0.0</distortionK1>
            <distortionK2>0.0</distortionK2>
            <distortionK3>0.0</distortionK3>
            <distortionT1>0.0</distortionT1>
            <distortionT2>0.0</distortionT2>
          </plugin>
          <pose frame=''>0.02 -0.07 0.061 0 -0 0</pose>
        </sensor>
        <gravity>1</gravity>
        <velocity_decay/>
        <self_collide>0</self_collide>
        <gravity>1</gravity>
        <gravity>1</gravity>
        <velocity_decay/>
        <sensor name='openni_camera_camera' type='depth'>
          <always_on>0</always_on>
          <update_rate>30</update_rate>
          <visualize>1</visualize>
          <camera name='__default__'>
            <horizontal_fov>1.047</horizontal_fov>
            <image>
              <width>640</width>
              <height>480</height>
              <format>B8G8R8</format>
            </image>
            <depth_camera>
              <output>depths</output>
            </depth_camera>
            <clip>
              <near>0.1</near>
              <far>100</far>
            </clip>
          </camera>
          <plugin name='head_rgbd_sensor_controller' filename='libhsrb_gazebo_ros_openni_kinect.so'>
            <alwaysOn>true</alwaysOn>
            <baseline>0.2</baseline>
            <updateRate>1.0</updateRate>
            <cameraName>head_rgbd_sensor</cameraName>
            <frameName>head_rgbd_sensor_rgb_frame</frameName>
            <robotNamespace>/hsrb</robotNamespace>
            <imageTopicName>//hsrb/head_rgbd_sensor/rgb/image_rect_color</imageTopicName>
            <cameraInfoTopicName>//hsrb/head_rgbd_sensor/rgb/camera_info</cameraInfoTopicName>
            <depthImageTopicName>//hsrb/head_rgbd_sensor/depth_registered/image_rect_raw</depthImageTopicName>
            <pointCloudTopicName>//hsrb/head_rgbd_sensor/depth_registered/rectified_points</pointCloudTopicName>
            <depthImageCameraInfoTopicName>//hsrb/head_rgbd_sensor/depth_registered/camera_info</depthImageCameraInfoTopicName>
            <pointCloudCutoff>0.5</pointCloudCutoff>
            <pointCloudCutoffMax>9.2</pointCloudCutoffMax>
            <distortionK1>0.0</distortionK1>
            <distortionK2>0.0</distortionK2>
            <distortionK3>0.0</distortionK3>
            <distortionT1>0.0</distortionT1>
            <distortionT2>0.0</distortionT2>
            <CxPrime>0.0</CxPrime>
            <Cx>0.0</Cx>
            <Cy>0.0</Cy>
            <focalLength>0.0</focalLength>
            <hackBaseline>0</hackBaseline>
            <encoding>16UC1</encoding>
          </plugin>
          <pose frame=''>-0.079796 0.022 0.215172 0 -0 0</pose>
        </sensor>
        <kinematic>0</kinematic>
      </link>
      <joint name='head_tilt_joint' type='revolute'>
        <child>head_tilt_link</child>
        <parent>head_pan_link</parent>
        <axis>
          <xyz>0 -1 0</xyz>
          <limit>
            <lower>-1.57</lower>
            <upper>0.52</upper>
            <effort>100</effort>
            <velocity>1</velocity>
          </limit>
          <dynamics>
            <damping>10</damping>
            <friction>0</friction>
            <spring_reference>0</spring_reference>
            <spring_stiffness>0</spring_stiffness>
          </dynamics>
          <use_parent_model_frame>1</use_parent_model_frame>
        </axis>
        <physics>
          <ode>
            <limit>
              <cfm>0</cfm>
              <erp>0.2</erp>
            </limit>
          </ode>
        </physics>
      </joint>
      <plugin name='torso_mimic_plugin' filename='libtmc_gazebo_mimic_plugin.so'>
        <joint>torso_lift_joint</joint>
        <mimicJoint>arm_lift_joint</mimicJoint>
        <multiplier>0.5</multiplier>
        <robotNamespace>/</robotNamespace>
      </plugin>
      <plugin name='ft_sensor' filename='libgazebo_ros_ft_sensor.so'>
        <updateRate>30.0</updateRate>
        <topicName>hsrb/wrist_wrench/raw</topicName>
        <jointName>wrist_ft_sensor_frame_joint</jointName>
        <robotNamespace/>
      </plugin>
      <plugin name='hsrb_hrh_gripper_plugin' filename='libtmc_gazebo_hrh_gripper.so'>
        <sensitiveness>0.05</sensitiveness>
        <update_rate>1000.0</update_rate>
        <max_torque>8.0</max_torque>
        <error_tolerance>0.0872</error_tolerance>
        <stall_timeout>2.0</stall_timeout>
        <robot_namespace>/hsrb</robot_namespace>
        <robotNamespace>/</robotNamespace>
      </plugin>
      <plugin name='hsrb_grasp_hack_plugin' filename='libhsrb_grasp_hack.so'>
        <grasp_check>
          <attach_steps>1</attach_steps>
          <detach_steps>2</detach_steps>
          <min_contact_count>1</min_contact_count>
          <max_attach_weight>1.2</max_attach_weight>
        </grasp_check>
        <gripper_link>hand_r_distal_link</gripper_link>
        <gripper_link>hand_l_distal_link</gripper_link>
        <gripper_link>hand_r_spring_proximal_link</gripper_link>
        <gripper_link>hand_l_spring_proximal_link</gripper_link>
        <palm_link>wrist_ft_sensor_frame</palm_link>
        <robot_namespace>/hsrb</robot_namespace>
        <robotNamespace>/</robotNamespace>
      </plugin>
      <static>0</static>
      <plugin name='hsrb_ros_control' filename='libhsrb_gazebo_ros_control.so'>
        <robotNamespace>/hsrb</robotNamespace>
        <legacyModeNS>false</legacyModeNS>
      </plugin>
      <plugin name='hsrb_p3d_ground_truth' filename='libgazebo_ros_p3d.so'>
        <robotNamespace>/hsrb</robotNamespace>
        <bodyName>base_footprint</bodyName>
        <topicName>odom_ground_truth</topicName>
        <frameName>map</frameName>
        <updateRate>30</updateRate>
      </plugin>
      <pose frame=''>0 0 0 0 -0 0</pose>
    </model>
    <gui fullscreen='0'>
      <camera name='user_camera'>
        <pose frame=''>2.06871 3.25497 17.9375 -0 1.3298 -1.6432</pose>
        <view_controller>orbit</view_controller>
        <projection_type>perspective</projection_type>
      </camera>
    </gui>
    <gravity>0 0 -9.8</gravity>
    <magnetic_field>6e-06 2.3e-05 -4.2e-05</magnetic_field>
    <atmosphere type='adiabatic'/>
    <spherical_coordinates>
      <surface_model>EARTH_WGS84</surface_model>
      <latitude_deg>0</latitude_deg>
      <longitude_deg>0</longitude_deg>
      <elevation>0</elevation>
      <heading_deg>0</heading_deg>
    </spherical_coordinates>
    <light name='user_spot_light_0_clone' type='spot'>
      <pose frame=''>1.27956 0.057828 2.14718 0 -0 0</pose>
      <diffuse>0.498039 0.498039 0.498039 1</diffuse>
      <specular>0.0980392 0.0980392 0.0980392 1</specular>
      <direction>0 0 -1</direction>
      <attenuation>
        <range>20</range>
        <constant>0.5</constant>
        <linear>0.01</linear>
        <quadratic>0.001</quadratic>
      </attenuation>
      <cast_shadows>1</cast_shadows>
      <spot>
        <inner_angle>0.6</inner_angle>
        <outer_angle>3</outer_angle>
        <falloff>1</falloff>
      </spot>
    </light>
    <light name='user_spot_light_0_clone_clone' type='spot'>
      <pose frame=''>-0.800722 0.128329 2.14718 0 -0 0</pose>
      <diffuse>0.498039 0.498039 0.498039 1</diffuse>
      <specular>0.0980392 0.0980392 0.0980392 1</specular>
      <direction>0 0 -1</direction>
      <attenuation>
        <range>20</range>
        <constant>0.5</constant>
        <linear>0.01</linear>
        <quadratic>0.001</quadratic>
      </attenuation>
      <cast_shadows>1</cast_shadows>
      <spot>
        <inner_angle>0.6</inner_angle>
        <outer_angle>3</outer_angle>
        <falloff>1</falloff>
      </spot>
    </light>
    <state world_name='default'>
      <sim_time>350 513000000</sim_time>
      <real_time>52 58577539</real_time>
      <wall_time>1595466873 897168918</wall_time>
      <iterations>36227</iterations>
      <model name='ground_plane'>
        <pose frame=''>0 0 0 0 -0 0</pose>
        <scale>1 1 1</scale>
        <link name='link'>
          <pose frame=''>0 0 0 0 -0 0</pose>
          <velocity>0 0 0 0 -0 0</velocity>
          <acceleration>0 0 0 0 -0 0</acceleration>
          <wrench>0 0 0 0 -0 0</wrench>
        </link>
      </model>
      <model name='hsrb'>
        <pose frame=''>0.023033 0.037232 -0.000115 0.000211 -0.000239 -0.001974</pose>
        <scale>1 1 1</scale>
        <link name='arm_flex_link'>
          <pose frame=''>0.164093 0.114869 0.389922 0.000184 -0.000182 -0.001991</pose>
          <velocity>0.002413 0.0023 -4.3e-05 5.9e-05 -0.00238 -0.001231</velocity>
          <acceleration>0.671889 -1.04967 -0.085323 -3.11432 1.33609 0.642497</acceleration>
          <wrench>0.899855 -1.40581 -0.114272 0 -0 0</wrench>
        </link>
        <link name='arm_lift_link'>
          <pose frame=''>0.022939 0.037152 0.389876 0.000168 -0.000235 -0.001991</pose>
          <velocity>0.002397 0.002638 0.000338 -0.001444 0.003449 -0.001242</velocity>
          <acceleration>0.851731 -0.689553 0.159977 -2.68633 -0.131793 -2.13661</acceleration>
          <wrench>1.08665 -0.879746 0.204102 0 -0 0</wrench>
        </link>
        <link name='arm_roll_link'>
          <pose frame=''>0.16903 0.114797 0.734922 0.000183 0.000176 -1.57198</pose>
          <velocity>0.001597 0.002329 -2.6e-05 -0.000458 -0.002373 0.000913</velocity>
          <acceleration>-0.072452 -1.01102 -0.052177 -1.4384 -0.704541 -0.310932</acceleration>
          <wrench>-0.017964 -0.250669 -0.012937 0 -0 0</wrench>
        </link>
        <link name='base_b_bumper_link'>
          <pose frame=''>0.023036 0.038532 -0.000114 -0.000212 0.000239 3.13962</pose>
          <velocity>0.001221 0.003373 0.000179 0.002658 0.003177 0.00035</velocity>
          <acceleration>-1.04356 1.10352 0.275089 -0.935968 -0.281834 0.816759</acceleration>
          <wrench>-0.062613 0.066211 0.016505 0 -0 0</wrench>
        </link>
        <link name='base_f_bumper_link'>
          <pose frame=''>0.023033 0.037232 -0.000115 0.000212 -0.000239 -0.001974</pose>
          <velocity>0.001221 0.003373 0.000176 0.002658 0.003177 0.00035</velocity>
          <acceleration>-1.04252 1.10352 0.268163 -0.935964 -0.281717 0.816791</acceleration>
          <wrench>-0.062551 0.066211 0.01609 0 -0 0</wrench>
        </link>
        <link name='base_footprint'>
          <pose frame=''>0.023033 0.037232 -0.000115 0.000211 -0.000239 -0.001974</pose>
          <velocity>0.001221 0.003364 0.000176 0.002594 0.00317 0.000375</velocity>
          <acceleration>0.018014 0.141788 0.394382 -1.06524 -0.297648 0.861558</acceleration>
          <wrench>0.901055 7.09222 19.727 0 -0 0</wrench>
        </link>
        <link name='base_l_drive_wheel_link'>
          <pose frame=''>-0.147861 0.012965 0.039881 -3.14143 -0.958697 -2.12095</pose>
          <velocity>0.001912 0.002781 0.000939 -0.069397 0.047716 0.001721</velocity>
          <acceleration>0.315064 -0.138653 1.64257 -2.56444 1.43991 -2.55284</acceleration>
          <wrench>0.063013 -0.027731 0.328514 0 -0 0</wrench>
        </link>
        <link name='base_l_passive_wheel_x_frame'>
          <pose frame=''>0.054282 0.193424 0.029974 0.303818 -0.00031 1.02078</pose>
          <velocity>0.001166 0.003112 0.004147 0.000863 3e-06 0.001753</velocity>
          <acceleration>-1.21935 0.577254 8.20938 1.77523 -0.355132 -2.50554</acceleration>
          <wrench>-0.24387 0.115451 1.64188 0 -0 0</wrench>
        </link>
        <link name='base_l_passive_wheel_y_frame'>
          <pose frame=''>0.054282 0.193424 0.029987 0.593161 1.00606 1.53854</pose>
          <velocity>0.001152 0.003058 0.006849 -0.079813 0.049464 0.03142</velocity>
          <acceleration>-1.24886 0.468482 13.6346 1.50606 -0.176591 -2.40773</acceleration>
          <wrench>-0.249772 0.093696 2.72693 0 -0 0</wrench>
        </link>
        <link name='base_l_passive_wheel_z_link'>
          <pose frame=''>0.054281 0.193423 0.030001 -1.00274 -0.60085 -1.05209</pose>
          <velocity>0.00105 0.002777 0.009573 -0.092376 0.034917 0.021931</velocity>
          <acceleration>-1.46179 -0.098926 19.1017 3.01912 -1.4448 -0.301969</acceleration>
          <wrench>-0.292359 -0.019785 3.82034 0 -0 0</wrench>
        </link>
        <link name='base_r_drive_wheel_link'>
          <pose frame=''>0.07891 -0.126075 0.039903 -3.14145 0.853805 -2.12071</pose>
          <velocity>0.002023 0.002975 -0.000188 -0.074263 0.050498 0.001697</velocity>
          <acceleration>0.574679 0.311235 -0.53306 1.89395 1.49307 0.540141</acceleration>
          <wrench>0.114936 0.062247 -0.106612 0 -0 0</wrench>
        </link>
        <link name='base_r_passive_wheel_x_frame'>
          <pose frame=''>0.148058 0.135927 0.029977 0.110125 -0.000305 1.02078</pose>
          <velocity>0.001412 0.003419 -0.002566 -0.000164 5.7e-05 0.00174</velocity>
          <acceleration>-0.710461 1.21863 -5.19693 -0.267683 -0.216147 -2.53065</acceleration>
          <wrench>-0.142092 0.243727 -1.03939 0 -0 0</wrench>
        </link>
        <link name='base_r_passive_wheel_y_frame'>
          <pose frame=''>0.148058 0.135927 0.029985 2.269 1.42682 -2.98825</pose>
          <velocity>0.00147 0.003435 -0.004718 -0.076037 0.046572 0.011582</velocity>
          <acceleration>-0.597589 1.25053 -9.4875 0.083575 -0.432868 -2.57351</acceleration>
          <wrench>-0.119518 0.250106 -1.8975 0 -0 0</wrench>
        </link>
        <link name='base_r_passive_wheel_z_link'>
          <pose frame=''>0.148057 0.135926 0.029994 -1.67059 -0.387689 -0.50191</pose>
          <velocity>0.001764 0.003548 -0.006881 -0.068373 0.059144 0.010217</velocity>
          <acceleration>-0.015448 1.47565 -13.7988 0.618376 0.022463 -2.64072</acceleration>
          <wrench>-0.00309 0.29513 -2.75976 0 -0 0</wrench>
        </link>
        <link name='base_roll_link'>
          <pose frame=''>0.023033 0.037232 -8.4e-05 -9.4e-05 -0.00031 1.02078</pose>
          <velocity>0.001376 0.003273 0.000429 0.003028 0.003485 0.001778</velocity>
          <acceleration>-0.212783 0.415424 0.711917 1.67248 0.847548 0.650618</acceleration>
          <wrench>-2.17877 4.25369 7.2896 0 -0 0</wrench>
        </link>
        <link name='hand_l_distal_link'>
          <pose frame=''>0.190924 -0.078166 0.706044 -2.90842 -1.57011 -1.85159</pose>
          <velocity>8.5e-05 0.002655 -3.8e-05 0.00025 9.5e-05 0.000215</velocity>
          <acceleration>0.091514 2.65084 -0.043489 0.250191 0.094668 0.214715</acceleration>
          <wrench>0.004368 0.126528 -0.002076 0 -0 0</wrench>
        </link>
        <link name='hand_l_mimic_distal_link'>
          <pose frame=''>0.190924 -0.078166 0.706044 -2.89595 -1.57011 -1.85165</pose>
          <velocity>8.5e-05 0.002662 -3.7e-05 0.000249 9.5e-05 -2e-06</velocity>
          <acceleration>0.08525 2.66157 -0.037442 0.249164 0.095028 -0.001683</acceleration>
          <wrench>0.000853 0.026616 -0.000374 0 -0 0</wrench>
        </link>
        <link name='hand_l_proximal_link'>
          <pose frame=''>0.19339 -0.00821 0.706092 -2.90953 -1.5701 -1.84543</pose>
          <velocity>0.001788 0.002593 -2.4e-05 8.5e-05 0.000101 -0.054723</velocity>
          <acceleration>-0.192352 -0.45661 -0.024271 -0.071698 0.108352 0.006173</acceleration>
          <wrench>-0.001924 -0.004566 -0.000243 0 -0 0</wrench>
        </link>
        <link name='hand_l_spring_proximal_link'>
          <pose frame=''>0.19339 -0.00821 0.706092 -2.87957 -1.57011 -1.86805</pose>
          <velocity>0.001788 0.002589 -1.8e-05 0.000233 6.8e-05 -0.024326</velocity>
          <acceleration>-0.133081 -0.477813 -0.015888 -0.037826 -0.884337 0.552201</acceleration>
          <wrench>-0.005801 -0.020827 -0.000693 0 -0 0</wrench>
        </link>
        <link name='hand_motor_dummy_link'>
          <pose frame=''>0.168866 -0.025693 0.722825 -2.90967 -1.5701 -1.84524</pose>
          <velocity>0.00181 0.002529 -2.5e-05 7.8e-05 6.4e-05 0</velocity>
          <acceleration>1.81027 2.52886 -0.025356 0.077621 0.064422 7.9e-05</acceleration>
          <wrench>0.018103 0.025289 -0.000254 0 -0 0</wrench>
        </link>
        <link name='hand_r_distal_link'>
          <pose frame=''>0.139766 -0.077999 0.706035 -2.90894 -1.57011 -1.84455</pose>
          <velocity>0.000179 0.002624 -3e-05 0.000159 9.8e-05 -0.000654</velocity>
          <acceleration>0.164021 2.61474 -0.034778 0.158803 0.097492 -0.651825</acceleration>
          <wrench>0.005073 0.080866 -0.001076 0 -0 0</wrench>
        </link>
        <link name='hand_r_mimic_distal_link'>
          <pose frame=''>0.139766 -0.077999 0.706035 -2.93384 -1.57011 -1.84463</pose>
          <velocity>0.000179 0.002629 -3e-05 0.000158 9.8e-05 -2e-06</velocity>
          <acceleration>0.179244 2.62866 -0.029638 0.158263 0.097893 -0.001587</acceleration>
          <wrench>0.001792 0.026287 -0.000296 0 -0 0</wrench>
        </link>
        <link name='hand_r_proximal_link'>
          <pose frame=''>0.14439 -0.008152 0.706083 -2.89935 -1.5701 -1.84537</pose>
          <velocity>0.001788 0.002522 -2.1e-05 0.000109 0.000182 -0.175327</velocity>
          <acceleration>-0.191811 -0.518558 -0.019362 -0.069637 0.108756 0.021892</acceleration>
          <wrench>-0.001918 -0.005186 -0.000194 0 -0 0</wrench>
        </link>
        <link name='hand_r_spring_proximal_link'>
          <pose frame=''>0.14439 -0.008152 0.706083 -2.91689 -1.57011 -1.8616</pose>
          <velocity>0.001788 0.002515 -1.8e-05 0.000157 8.9e-05 -0.023039</velocity>
          <acceleration>-0.139672 -0.539948 -0.013851 0.209498 0.148264 0.029397</acceleration>
          <wrench>-0.006139 -0.023734 -0.000609 0 -0 0</wrench>
        </link>
        <link name='head_pan_link'>
          <pose frame=''>0.02285 0.03707 0.765154 0.00022 -0.000242 -0.00198</pose>
          <velocity>0.003447 0.001559 0.000114 0.002927 0.002875 -0.004535</velocity>
          <acceleration>2.96972 -2.38686 0.184265 0.497915 -0.383064 1.59366</acceleration>
          <wrench>1.69839 -1.36505 0.105382 0 -0 0</wrench>
        </link>
        <link name='head_tilt_link'>
          <pose frame=''>0.04285 0.037031 0.765157 0.000187 -0.001173 -0.001987</pose>
          <velocity>0.003399 0.001548 8.6e-05 0.001603 -0.008778 -0.004705</velocity>
          <acceleration>1.01968 -2.37905 -0.772946 0.099902 1.47639 -1.60822</acceleration>
          <wrench>2.24717 -5.24295 -1.70342 0 -0 0</wrench>
        </link>
        <link name='torso_lift_link'>
          <pose frame=''>0.02285 0.037071 0.765155 0.00021 -0.000238 -0.001975</pose>
          <velocity>0.003505 0.001528 9.3e-05 0.002527 0.003099 0.00038</velocity>
          <acceleration>1.55969 -1.17267 0.480523 -1.20211 -0.434012 0.840326</acceleration>
          <wrench>5.33537 -4.01144 1.64376 0 -0 0</wrench>
        </link>
        <link name='wrist_flex_link'>
          <pose frame=''>0.16903 0.114797 0.734921 2.8768 1.5701 1.30482</pose>
          <velocity>0.001601 0.002331 -2.5e-05 8.3e-05 -0.002391 0.001369</velocity>
          <acceleration>-0.353656 -0.942628 -0.070661 0.707473 0.832246 0.24314</acceleration>
          <wrench>-0.24092 -0.642142 -0.048136 0 -0 0</wrench>
        </link>
        <link name='wrist_ft_sensor_frame'>
          <pose frame=''>0.168943 0.041299 0.73487 -0.269552 1.5701 1.30006</pose>
          <velocity>0.001721 0.00253 -2e-05 7.8e-05 6.3e-05 0.001343</velocity>
          <acceleration>-0.224361 -0.538792 -0.025983 -0.063782 0.115883 0.978036</acceleration>
          <wrench>-0.211279 -0.507376 -0.024468 0 -0 0</wrench>
        </link>
        <link name='wrist_ft_sensor_mount_link'>
          <pose frame=''>0.16903 0.114801 0.73492 2.87194 1.5701 1.29996</pose>
          <velocity>0.001635 0.002651 -9e-06 8.2e-05 6.4e-05 0.001304</velocity>
          <acceleration>-0.290366 -0.293257 -0.021262 -0.05762 0.108642 0.895775</acceleration>
          <wrench>-0.002904 -0.002933 -0.000213 0 -0 0</wrench>
        </link>
      </model>
      <model name='hsrb_square'>
        <pose frame=''>0 0 0 0 -0 0</pose>
        <scale>1 1 1</scale>
        <link name='link'>
          <pose frame=''>3.2 0 0 0 -0 0</pose>
          <velocity>0 0 0 0 -0 0</velocity>
          <acceleration>0 0 0 0 -0 0</acceleration>
          <wrench>0 0 0 0 -0 0</wrench>
        </link>
        <link name='link_clone'>
          <pose frame=''>-3.2 0 0 0 -0 0</pose>
          <velocity>0 0 0 0 -0 0</velocity>
          <acceleration>0 0 0 0 -0 0</acceleration>
          <wrench>0 0 0 0 -0 0</wrench>
        </link>
        <link name='link_clone_clone'>
          <pose frame=''>0 3.2 0 0 -0 1.57</pose>
          <velocity>0 0 0 0 -0 0</velocity>
          <acceleration>0 0 0 0 -0 0</acceleration>
          <wrench>0 0 0 0 -0 0</wrench>
        </link>
        <link name='link_clone_clone_clone'>
          <pose frame=''>0 -3.2 0 0 -0 1.57</pose>
          <velocity>0 0 0 0 -0 0</velocity>
          <acceleration>0 0 0 0 -0 0</acceleration>
          <wrench>0 0 0 0 -0 0</wrench>
        </link>
      </model>
      <light name='user_spot_light_0_clone'>
        <pose frame=''>2.5 0 2 0 1 0</pose>
      </light>
      <light name='user_spot_light_0_clone_clone'>
        <pose frame=''>-2.5 0 2 0 -1 0</pose>
      </light>
    </state>
  </world>
</sdf>
